Workbook
Name AssocBook: Inputs!$F$161:$F$161
Name AssocClose: Inputs!$E$161:$E$161
Name AssocDiscount: Inputs!$H$159
Name AssocLines: Bridge!$C$17
Name AssocReplaced: Bridge!$C$19
Name AssocShares: Inputs!$D$161:$D$161
Name AssocValue: Bridge!$C$18
Name BetaL: WACC!$C$16
Name BetaPubN: Inputs!$B$130
Name BetaPubR2: Inputs!$B$132
Name BetaPubU: Inputs!$B$131
Name BetaR2Median: WACC!$C$7
Name BetaR2Warn: Inputs!$B$37
Name BetaU: WACC!$C$6
Name BetaWarn: WACC!$C$8
Name Block_q1: Premium!$C$23
Name Block_q2: Premium!$C$24
Name Block_q3: Premium!$C$25
Name BlumeC: Inputs!$B$32
Name BlumeW: Inputs!$B$31
Name BorrowAmt: Inputs!$C$125:$C$125
Name BorrowRate: Inputs!$B$125:$B$125
Name BridgeAdj: Bridge!$C$22
Name BsAmt: FS_Hist!$D$33:$D$37
Name BsClass: FS_Hist!$C$33:$C$37
Name BsName: FS_Hist!$A$33:$A$37
Name CAGR: Forecast!$C$24
Name CapexRatio: Forecast!$F$15
Name CfStart: Inputs!$B$14
Name CheckTable: Checks!$B$6:$F$74
Name ClipHi: Inputs!$B$64
Name ClipLo: Inputs!$B$63
Name Close: Inputs!$B$44
Name COGSR: Forecast!$F$16
Name CommonIssued: Inputs!$B$40
Name CommonTreasury: Inputs!$B$41
Name ConvEngine: Convergence!$A$7:$F$8
Name ConvLive: Convergence!$A$13:$F$14
Name ConvShare: Inputs!$B$61
Name DaysYr: Inputs!$B$15
Name DE_Target: Inputs!$B$33
Name DiagCandTable: Diagnostics!$A$58:$D$60
Name DiagCompTable: Diagnostics!$A$37:$C$44
Name DiagDcf: Diagnostics!$B$5
Name DiagDcfEngine: Diagnostics!$B$6
Name DiagDnaTable: Diagnostics!$A$133:$D$139
Name DiagFlagTable: Diagnostics!$A$48:$C$54
Name DiagGuardTable: Diagnostics!$A$120:$B$120
Name DiagHeadline: Diagnostics!$B$120
Name DiagLight: Diagnostics!$B$23
Name DiagLightCheck: Diagnostics!$B$25
Name DiagLightEngine: Diagnostics!$B$24
Name DiagLightMkt: Diagnostics!$B$22
Name DiagLightPeer: Diagnostics!$B$21
Name DiagMistagTable: Diagnostics!$A$161:$D$161
Name DiagMktRatio: Diagnostics!$B$14
Name DiagOtherTable: Diagnostics!$B$93:$D$117
Name DiagPeerBasis: Diagnostics!$B$7
Name DiagPeerMed: Diagnostics!$B$9
Name DiagPeerN: Diagnostics!$B$11

Sheet Cover
B2: 솔본 (035610) 주식가치 산정 모델 (자동 생성 초안)
B3: 자동 생성 초안. 기계적 가치산정 결과이며 전문가 판단을 거친 가치평가(평가보고서)가 아님. 투자 권유 아님
B4: 예시 입력 시세(실제 종가 아님) — 결과는 가정 하의 추정 내재가치 예시
B5: 평가대상 | C5: 솔본 (KOSDAQ 035610, 법인 00249982)
B6: 평가기준일 | C6: 2026-09-30
B7: 재무 기준일 | C7: 2026-06-30 (반기보고서)
B8: 기준가치 | C8: 주당 내재가치 추정(가치산정, 가정 하의 예시). '공정가치'(K-IFRS 1113·자본시장법 공정가액)가 아님
B9: 평가 전제 | C9: 계속기업
B10: 목적 | C10: 방법론 예시·교육(실제 거래·공시용 아님)
B11: 평가 구조 | C11: 연결 DCF − 비지배지분
B12: 단위 | C12: 백만원(주당 값은 원). 비율은 %
B13: 출처 표시 | C13: 재무: DART 접수번호 / 금리: ECOS 817Y002 / 시세·시가총액·VWAP·베타: 한국거래소 통계정보(기준일 단일 값·집계만)
B14: 생성 | C14: src/excel/build.py ← 공개 배포 작업 공간/sessions/035610_20260930_001/v1_public/valuation_035610_035610_20260930_001v1p.yaml (P4, 엔진 형태 mechanical). 결과 확인: Checks 시트의 master check
B17: 현재 선택 | C17: ="시나리오: "&ScenSel&" / SRP: "&TEXT(SRP_Sel,"0.0%")&" / 주당 가치(Gordon): "&TEXT(PerShare,"#,##0")&"원" -> 시나리오: 기본 / SRP: 0.0% / 주당 가치(Gordon): 8,734원
B18: master check | C18: =MasterCheck -> OK
B20: 사람이 작성할 칸
B21: 평가방법 선택 근거
B22: 주요 가정의 합리성
B23: 평가상 한계
B24: 검토자·검토일

Sheet Guide
B2: 모델 안내
B4: 시트 지도
B5: Inputs | C5: 모든 입력값(파란 글씨·노란 바탕). 출처·기준일·상태(✅/🔸/⚠️) 열. 시나리오·SRP·RONIC 규칙 선택 칸이 맨 위
B6: FS_Hist | C6: 엔진이 쓴 과거 재무(모회사 별도, 연결 2026-06-30)와 부문 주석, 열마다 DART 접수번호
B7: Forecast | C7: 선택한 시나리오의 2H26~2040 예측: 매출·EBIT·D&A·CAPEX·ΔNWC·누진 세금·NOPAT·FCFF. 2032까지 명시, 2033~2040 체감
B8: WACC | C8: 피어 베타(원 β → Blume → Hamada 언레버 → 중앙값) → 리레버 → Ke, Kd 규칙(등급·Rf 하한), WACC, R² 경고
B9: DCF | C9: 할인계수(mid-year, 6/30 할인 → 9/30 이월), RONIC, 가치동인 영구가치, EV, 영구가치 비중, 함의 배수, Exit 병행
B10: Bridge | C10: 연결 EV − 순차입금(리스 포함) + 비영업 − 비지배 → 주당 가치. 계열사 대여금 표시·토글, 구조 판단
B11: Peers | C11: 피어 배수 4종(LTM), N/M 처리, 사분위(QUARTILE.INC) → 주당 가치
B12: Premium | C12: 시총 백분위와 D6 적용 규칙(method·이유) → 20일 VWAP × (1+프리미엄) 블록 1주당 범위, 상증법 할증 비교
B13: Scenarios | C13: 시나리오 3 × SRP 3 표(살아 있는 수식, Scen_Calc), 데이터 표 2개(WACC×g, 성장×이익률, 엑셀 What-If), 역DCF(엔진 값)
B14: Scen_Calc | C14: Scenarios 표를 계산하는 시나리오별 블록(Forecast와 같은 수식, 시나리오 고정)
B15: Football | C15: 방법별 주당 범위 그림(수식 셀 참조) + 기준일 종가 선
B16: Convergence | C16: 수렴 시험(사전 고정 기준): 엔진 기록 판정(C2 1차, C3)과 살아 있는 모델 재계산
... B28: P5-B 참고값(P6-A) | C28: Forecast 사업계획 검증 옆 달성률 표, Inputs SRP 옆 한공회 인용 표는 스팩 합병 외부평가 의견서 집계(회색, 표시만). 자동 감액·경고 판정 없음

Sheet Inputs
A1: Inputs — 입력값 (파란 글씨·노란 바탕 칸만 바꾼다)
A2: 단위: 백만원(주당 값은 원). 출처 열: DART 접수번호·ECOS 코드·config 경로. 상태: ✅ 1차 출처·독립 확인 / 🔸 단일 출처·직접 계산 / ⚠️ 미확인·프로젝트 가정
A4: 항목 | B4: 값 | C4: 단위 | D4: 출처 | E4: 기준일 | F4: 상태 | G4: 근거·비고
A5: 1. 선택 (모델 실행)
A6: 시나리오 선택 | B6: 기본 | D6: 공개 배포 작업 공간/sessions/035610_20260930_001/v1_public/valuation_035610_035610_20260930_001v1p.yaml excel.default_scenario | F6: 🔸 | G6: 목록: 비관/기본/낙관
A7: SRP 선택(규모위험프리미엄) | B7: 0 | C7: % | D7: config/valuation_rf.yaml decisions.srp_columns (D4) | F7: ⚠️ | G7: 목록: SRP 열 세 값. 한공회 구간 표 미확보 → 세 열 병기
A8: Rf 만기 선택(5 = 국고채 5년, 10 = 국고채 10년) | B8: 5 | C8: 년 | D8: config/valuation_rf.yaml risk_free.tenor | F8: 🔸 | G8: 기본 5년(P3 공통 장부, 사전 고정 결과 그대로). 10년 = 선택: P5-B 의견서 Rf 만기 표시 57건 중 10년 56건(reports/p5b_final.md 7절) → 10년을 선택 칸으로 추가. 기본 5년 불변
A9: RONIC 출발점 규칙 | B9: normal | D9: config/valuation_rules.yaml common_rules.ronic | F9: 🔸 | G9: normal = P3-C3 공통 규칙(FY2026 매출 × 정상 이익률) / mixed = P3-B2·C2 방식(1H 실적 + 2H 정상)
A11: 2. 기준일·기간 구조
A12: 평가기준일 | B12: 46295 | C12: 날짜 | D12: 공개 배포 작업 공간/sessions/035610_20260930_001/v1_public/valuation_035610_035610_20260930_001v1p.yaml meta.as_of | E12: 2026-09-30 | F12: 🔸 | G12: KRX 시세 마지막 적재 거래일
A13: 할인 기준일(재무상태표일) | B13: 46203 | C13: 날짜 | D13: 공개 배포 작업 공간/sessions/035610_20260930_001/v1_public/valuation_035610_035610_20260930_001v1p.yaml meta.bs_date | F13: 🔸 | G13: 순현금(6/30 재무상태표)과 시작점을 맞춘다. EV는 평가기준일로 이월
A14: 현금흐름 시작일 | B14: 46204 | C14: 날짜 | D14: 공개 배포 작업 공간/sessions/035610_20260930_001/v1_public/valuation_035610_035610_20260930_001v1p.yaml meta.bs_date + 1일 | F14: 🔸
A15: 연 일수 | B15: 365 | C15: 일 | D15: src/valuation/dcf.py DAYS | F15: 🔸 | G15: 할인 기간·회전일수 계산(윤일 포함 실제 일수 ÷ 365)
A16: 단위 환산 | B16: 1000000 | C16: 원/백만원 | D16: 단위 | F16: 🔸 | G16: 주당 가치 = 주식가치(백만원) × 1,000,000 ÷ 주식수
A17: mid-year 할인(1=예, 0=기말) | B17: 1 | D17: 공개 배포 작업 공간/sessions/035610_20260930_001/v1_public/valuation_035610_035610_20260930_001v1p.yaml forecast.mid_year | F17: 🔸
A18: 명시 기간 마지막 연도(생성 시 고정) | B18: 2032 | C18: 연도 | D18: company_dcf.EXPLICIT_END (P3-B2 구조) | F18: 🔸 | G18: 열 수가 생성 시 정해진다. 바꾸려면 config 수정 후 재생성(Checks에서 확인)
A19: 체감 구간 연수(생성 시 고정) | B19: 8 | C19: 년 | D19: p3b2.stages.fade_years | F19: ⚠️ | G19: g_t = g_2032 − k × (g_2032 − g) / 8
A20: 평가 구조(사용자 결정·규칙 판정) | B20: consolidated | D20: 공개 배포 작업 공간/sessions/035610_20260930_001/v1_public/valuation_035610_035610_20260930_001v1p.yaml structure (규칙 판정) | F20: 🔸 | G20: Bridge 시트의 구조 판단 규칙(valuation_rules.yaml) 결과와 같아야 한다
A22: 3. 할인율 (공통 장부)
A23: 무위험이자율 국고채 5년(기본) | B23: 0.04203 | C23: % | D23: ECOS 817Y002 010200001 (KTB5Y) | E23: 2026-09-30 | F23: ✅ | G23: 평가 표본 5년 48%·10년 39%(P3) → 5년 기본. 모델이 쓰는 Rf = WACC 시트 'Rf'(Rf 만기 선택)
A24: 무위험이자율 국고채 10년(선택) | B24: 0.04407 | C24: % | D24: ECOS 817Y002 010210000 (KTB10Y) | E24: 2026-09-30 | F24: ✅ | G24: P5-B 외부평가 의견서 Rf 만기 표시 57건 중 10년 56건(reports/p5b_final.md 7절) | I24: 참고: 한공회 규모위험 프리미엄 인용값(P5-B 외부평가 의견서 재인용 🔸, 집계)
A25: 시장위험프리미엄 MRP | B25: 0.08 | C25: % | D25: 한공회 MRP 가이던스 7~9%(2022 발표·2023 유지), 2026-05 설문 8.167%(CPA뉴스 2026-05-29, 한국세정신문 2026-05-29) | E25: 2026-05 | F25: ✅ | G25: 가이던스 7~9% 중앙값 | I25: 인용 기준 연도 | J25: 구간 이름 | K25: 값 | L25: 건수 | M25: 신고서 연도
A26: SRP 열 1 | B26: 0 | C26: % | D26: config/valuation_rf.yaml decisions.srp_columns | F26: ⚠️ | G26: 한공회 2026년 1월 기준 규모위험프리미엄 연구(기사 인용). 구간 경계·전체 표 원문 미확보 | I26: 2022 | J26: 3분위 | K26: 0.0335 | L26: 1 | M26: 2024
A27: SRP 열 2 | B27: 0.01 | C27: % | D27: config/valuation_rf.yaml decisions.srp_columns | F27: ⚠️ | I27: 2022 | J27: 5분위 | K27: 0.0416 | L27: 1 | M27: 2024
A28: SRP 열 3 | B28: 0.02 | C28: % | D28: config/valuation_rf.yaml decisions.srp_columns | F28: ⚠️ | I28: 2022 | J28: Micro | K28: 0.0335 | L28: 4 | M28: 2023~2024
A29: SRP 인용 참고값(한공회 Micro, 민감도 전용) | B29: 0.0402 | C29: % | D29: DB p5b_srp_cites: 가장 최근 신고서의 같은 구간 인용값(reports/p5b_final.md 8절) | E29: 20260821 | F29: 🔸 | G29: 의견서 2차 인용 3건(2025~2026 신고서). SRP 기본 열(결정 D4)은 그대로. Scenarios G 표에서만 쓴다 | I29: 2023 | J29: 5분위 | K29: 0.0473 | L29: 1 | M29: 2024
A30: Hamada 세율(언레버·리레버) | B30: 0.22 | C30: % | D30: 공개 배포 작업 공간/sessions/035610_20260930_001/v1_public/valuation_035610_035610_20260930_001v1p.yaml beta.tax | F30: 🔸 | G30: 피어 대부분의 과세표준 구간 한계세율 | I30: 2023 | J30: Micro | K30: 0.0335 | L30: 1 | M30: 2024
A31: Blume 가중치(원 β) | B31: 0.67 | D31: config/valuation_rules.yaml common_rules.beta.blume | F31: 🔸 | G31: Blume = 0.67 × 원 β + 0.33 | I31: 2024 | J31: (미추출) | K31: 0.0375 | L31: 1 | M31: 2025
A32: Blume 상수 | B32: 0.33 | D32: config/valuation_rules.yaml common_rules.beta.blume | F32: 🔸 | I32: 2024 | J32: 3분위 | K32: 0.0375 | L32: 1 | M32: 2025
A33: 목표 D/E (WACC) | B33: 0.0042596555 | C33: 배 | D33: 공개 배포 작업 공간/sessions/035610_20260930_001/v1_public/valuation_035610_035610_20260930_001v1p.yaml (공개 모드 집계 입력) | F33: 🔸 | G33: 자체 D/E 시점 평균(5개 시점, PC에서 계산한 집계값. 시점별 시가총액은 공개 모드에 표시하지 않음) | I33: 2024 | J33: 5분위 | K33: 0.0473 | L33: 1 | M33: 2024
A34: 신용등급(빈칸 = 무등급) | D34: 자동 탐색 안 함(OpenDART 등급 API 없음) — 사람 확인 | F34: 🔸 | G34: Kd 규칙: 무등급·BBB 이하 → BBB- 3년, AA- 이상 → AA-, A+~BBB+ → max(실제 가중, AA-), 하한 Rf | I34: 미추출 | J34: (미추출) | K34: 0.0335 | L34: 1 | M34: 2025
A35: 회사채 3년 BBB- | B35: 0.10506 | C35: % | D35: ECOS 817Y002 010320000 (CB3Y_BBBm) | E35: 2026-09-30 | F35: ✅ | I35: 미추출 | J35: 3분위 | K35: 0.0375 | L35: 1 | M35: 2025
A36: 회사채 3년 AA- | B36: 0.04703 | C36: % | D36: ECOS 817Y002 010300000 (CB3Y_AAm) | E36: 2026-09-30 | F36: ✅ | I36: 미추출 | J36: 3분위 | K36: 0.0402 | L36: 1 | M36: 2026
A37: 베타 신뢰성 경고 기준(피어 R² 중앙값 미만) | B37: 0.1 | D37: common_rules.beta.warn_r2_median_below | F37: 🔸 | G37: 표시만(경로 불변) | I37: 미추출 | J37: 5분위 | K37: 0.0416 | L37: 1 | M37: 2023
I38: 미추출 | J38: 5분위 | K38: 0.0466 | L38: 1 | M38: 2026
A39: 4. 주식·시장 (기준일 단일 값) | I39: 미추출 | J39: Micro | K39: 0.0402 | L39: 3 | M39: 2025~2026
A40: 보통주 발행주식수(기준일) | B40: 27345997 | C40: 주 | D40: 반기보고서 주식의 총수 20260814003092(stockTotqySttus), KRX 기준일 상장 우선주 | E40: 2026-09-30 | F40: ✅ | G40: 주당가치 = 주식가치 ÷ 보통주 유통주식수(우선주 없음) | I40: 구간 경계(시가총액)와 대상 회사가 속한 구간은 미확인. 같은 이름도 연구 기준 연도마다 값이 다름. 출처: reports/p5b_final.md (커밋 0a8d7c6), DB p5b_error·p5b_forecast·p5b_srp_cites
A41: 보통주 자기주식수(기준일) | B41: 0 | C41: 주 | D41: 반기보고서 주식의 총수 20260814003092(stockTotqySttus), KRX 기준일 상장 우선주 | E41: 2026-09-30 | F41: ✅
A42: 우선주 발행주식수(기준일) | B42: 0 | C42: 주 | D42: 반기보고서 주식의 총수 20260814003092(stockTotqySttus), KRX 기준일 상장 우선주 | E42: 2026-09-30 | F42: ✅ | G42: 우선주 없음
A43: 우선주 자기주식수(기준일) | B43: 0 | C43: 주 | D43: 반기보고서 주식의 총수 20260814003092(stockTotqySttus), KRX 기준일 상장 우선주 | E43: 2026-09-30 | F43: ✅
...

Sheet FS_Hist
A1: FS_Hist — 엔진이 쓴 과거 재무 (백만원, DART 정기보고서 API·원문 주석)
A2: 열마다 주 접수번호(가장 많은 줄의 출처), 기타 접수번호는 비교 칸 출처. 값이 없는 줄은 0(엔진과 같음). 입력 셀
A4: 재무제표 | C4: 별도(OFS) | D4: 별도(OFS) | E4: 별도(OFS) | F4: 별도(OFS) | G4: 별도(OFS) | H4: 별도(OFS) | I4: 별도(OFS) | J4: 별도(OFS)
A5: 기간 | C5: 2020 FY | D5: 2021 FY | E5: 2022 FY | F5: 2023 FY | G5: 2024 FY | H5: 2025 FY | I5: 2025 H1 | J5: 2026 H1
A6: 주 접수번호 | C6: 20220323000559 | D6: 20230721000054 | E6: 20240321001602 | F6: 20260320001033 | G6: 20260323000001 | H6: 20260323000001 | I6: 20260814003092 | J6: 20260814003092
A7: 기타 접수번호 | C7: - | D7: 20220323000559 | E7: 20230721000054 | F7: 20240321001602 | G7: 20260320001033 | H7: - | I7: 20250813001150 | J7: -
A8: 매출액 | B8: revenue | C8: 3540.8746 | D8: 3324.1199 | E8: 3307.0693 | F8: 4545.6638 | G8: 5169.9308 | H8: 3686.9784 | I8: 2598.7278 | J8: 1699.4526
A9: 매출원가 | B9: cogs | C9: 113.40545 | D9: 112.79845 | E9: 98.116134 | F9: 93.330299 | G9: 90.569449 | H9: 99.836631 | I9: 48.778481 | J9: 51.642809
A10: 영업이익 | B10: operating_income | C10: 1182.3769 | D10: 1374.8942 | E10: -324.43883 | F10: 1453.6667 | G10: 75.220169 | H10: -1794.8232 | I10: 772.55253 | J10: -259.27283
A11: pretax_income | B11: pretax_income | C11: 913.03956 | D11: 18012.262 | E11: -11344.259 | F11: 4885.3981 | G11: -5289.807 | H11: -4873.4799 | I11: 744.40479 | J11: 914.02463
A12: 당기순이익 | B12: net_income | C12: 913.03956 | D12: 18012.262 | E12: -11344.259 | F12: 4885.3981 | G12: -5289.807 | H12: -4873.4799 | I12: 562.22505 | J12: -21.678901
A13: net_income_parent | B13: net_income_parent | C13: 0 | D13: 0 | E13: 0 | F13: 0 | G13: 0 | H13: 0 | I13: 0 | J13: 0
A14: 유형자산 취득(CAPEX) | B14: capex_ppe | C14: 1.2 | D14: 3.9 | E14: 4.773637 | F14: 1.875 | G14: 69.992727 | H14: 93.67 | I14: 75.075 | J14: 8.4846
A15: 무형자산 취득 | B15: capex_intangibles | C15: 0 | D15: 0 | E15: 0 | F15: 0 | G15: 0 | H15: 0 | I15: 0 | J15: 0
A16: 감가상각비·무형자산상각비(주석) | B16: dna | D16: 129.868 | E16: 114.227 | F16: 103.232 | G16: 93.911 | H16: 116.591 | I16: 50.33 | J16: 70.66
A17: dna_dep | B17: dna_dep | C17: 0 | D17: 129.828 | E17: 114.187 | F17: 103.232 | G17: 93.911 | H17: 110.095 | I17: 50.33 | J17: 62.205
A18: 매출채권 | B18: receivables | C18: 13131.713 | D18: 9346.1395 | E18: 7010.9404 | F18: 2660.6366 | G18: 1286.9762 | H18: 570.96784 | I18: 1331.8225 | J18: 846.27433
A19: 재고자산 | B19: inventories | C19: 35.144 | D19: 2.47 | E19: 1.685 | F19: 0.935 | G19: 0.935 | H19: 0 | I19: 0.935 | J19: 0
A20: 매입채무 | B20: trade_payables | C20: 592.5531 | D20: 468.07143 | E20: 3486.4705 | F20: 2546.2337 | G20: 774.35165 | H20: 434.98341 | I20: 514.11926 | J20: 542.24401
A21: 유형자산 | B21: ppe | C21: 290.92026 | D21: 242.177 | E21: 209.94787 | F21: 185.77524 | G21: 292.72182 | H21: 306.97369 | I21: 314.42879 | J21: 300.29703
A22: 무형자산 | B22: intangibles | C22: 7.680093 | D22: 7.64 | E22: 7.64 | F22: 7.64 | G22: 7.64 | H22: 7.64 | I22: 7.64 | J22: 7.64
A23: 사용권자산 | B23: rou_assets | C23: 0 | D23: 0 | E23: 0 | F23: 0 | G23: 0 | H23: 23.584536 | I23: 0 | J23: 56.911371
A24: 총차입금(API 표준 계정) | B24: total_debt | C24: 0 | D24: 0 | E24: 0 | F24: 0 | G24: 1500 | H24: 0 | I24: 725.85642 | J24: 0
A25: 리스부채 | B25: lease_liabilities | C25: 0 | D25: 0 | E25: 0 | F25: 0 | G25: 0 | H25: 23.879169 | I25: 0 | J25: 55.459414
A26: 비지배지분 | B26: nci | C26: 0 | D26: 0 | E26: 0 | F26: 0 | G26: 0 | H26: 0 | I26: 0 | J26: 0
A27: 지배주주지분 | B27: equity_parent | C27: 0 | D27: 0 | E27: 0 | F27: 0 | G27: 0 | H27: 0 | I27: 0 | J27: 0
A28: 자본총계 | B28: total_equity | C28: 144863.02 | D28: 167740.11 | E28: 117746.92 | F28: 122562.28 | G28: 117240.74 | H28: 119185.57 | I28: 117802.97 | J28: 119163.89
A31: 연결 재무상태표 금융자산 줄 분류 (2026-06-30, 백만원) — 20260814003092 연결 재무상태표 줄(peer_p3.classify 규칙)
A32: 계정 | B32: 구간 | C32: 분류 | D32: 금액
A33: 현금및현금성자산 | B33: 유동 | C33: cash_like | D33: 1111.4503
A34: 투자부동산 | B34: 비유동 | C34: non_operating | D34: 26435.924
A35: 관계기업투자주식 | B35: 비유동 | C35: nonop_assoc | D35: 13228.925
A36: 종속기업투자주식 | B36: 비유동 | C36: sub_inv | D36: 70894.006
A37: 당기손익-공정가치측정금융자산 | B37: 비유동 | C37: non_operating | D37: 6060.6815
A38: 분류 cash_like = 현금성(유동: 현금·단기금융·공정가치·기타 유동 금융자산), non_operating = 비영업(비유동: 공정가치·장기금융·기타 금융자산·관계기업·투자부동산). 대상과 피어에 같은 규칙(peer_p3.classify) ⚠️ '기타 금융자산'에는 대여금이 섞일 수 있음

Sheet Forecast
A1: Forecast — 연결 예측(기계적 경로) (선택한 시나리오, 백만원)
A2: ="선택 시나리오: "&ScenSel&" (2H26~"&ExplicitEnd&" 명시, 이후 "&FadeYears&"년 체감 → 영구)" -> 선택 시나리오: 기본 (2H26~2032 명시, 이후 8년 체감 → 영구)
A4: 세율표(누진) — Inputs 표 1 연결, 한계세율 차이
C5: 하한 | D5: 상한 | E5: 세율 | F5: 세율 증분
A6: 구간 1 | C6: =Inputs!B98 -> 0 | D6: =IF(ISBLANK(Inputs!C98),"",Inputs!C98) -> 200 | E6: =Inputs!D98 -> 0.11 | F6: =E6 -> 0.11
A7: 구간 2 | C7: =Inputs!B99 -> 200 | D7: =IF(ISBLANK(Inputs!C99),"",Inputs!C99) -> 20000 | E7: =Inputs!D99 -> 0.22 | F7: =E7-N(E6) -> 0.11
A8: 구간 3 | C8: =Inputs!B100 -> 20000 | D8: =IF(ISBLANK(Inputs!C100),"",Inputs!C100) -> 300000 | E8: =Inputs!D100 -> 0.242 | F8: =E8-N(E7) -> 0.022
A9: 구간 4 | C9: =Inputs!B101 -> 300000 | D9: =IF(ISBLANK(Inputs!C101),"",Inputs!C101) | E9: =Inputs!D101 -> 0.275 | F9: =E9-N(E8) -> 0.033
A11: 기초 비율 — 연결 과거 값(FS_Hist), 과거 3년 평균
C12: FY2023 | D12: FY2024 | E12: FY2025 | F12: 평균
A13: 영업이익률 | C13: =(FS_Hist!$F$10)/(FS_Hist!$F$8) -> 0.31979196 | D13: =(FS_Hist!$G$10)/(FS_Hist!$G$8) -> 0.01454955 | E13: =(FS_Hist!$H$10)/(FS_Hist!$H$8) -> -0.48680058 | F13: =AVERAGE(C13:E13) -> -0.050819691
A14: D&A ÷ 매출 | C14: =IF(ISNUMBER(FS_Hist!$F$16),(FS_Hist!$F$16)/(FS_Hist!$F$8),"n/a") -> 0.022709995 | D14: =IF(ISNUMBER(FS_Hist!$G$16),(FS_Hist!$G$16)/(FS_Hist!$G$8),"n/a") -> 0.018164847 | E14: =IF(ISNUMBER(FS_Hist!$H$16),(FS_Hist!$H$16)/(FS_Hist!$H$8),"n/a") -> 0.031622372 | F14: =AVERAGE(C14:E14) -> 0.024165738
A15: CAPEX ÷ 매출(유형 + 무형) | C15: =(FS_Hist!$F$14+FS_Hist!$F$15)/(FS_Hist!$F$8) -> 0.00041248101 | D15: =(FS_Hist!$G$14+FS_Hist!$G$15)/(FS_Hist!$G$8) -> 0.013538426 | E15: =(FS_Hist!$H$14+FS_Hist!$H$15)/(FS_Hist!$H$8) -> 0.025405628 | F15: =AVERAGE(C15:E15) -> 0.013118845
A16: 매출원가율 | C16: =(FS_Hist!$F$9)/(FS_Hist!$F$8) -> 0.020531721 | D16: =(FS_Hist!$G$9)/(FS_Hist!$G$8) -> 0.017518503 | E16: =(FS_Hist!$H$9)/(FS_Hist!$H$8) -> 0.027078171 | F16: =AVERAGE(C16:E16) -> 0.021709465
A17: 매출채권 회전일수(매출 기준) | C17: =IF((FS_Hist!$F$8)=0,"n/a",(FS_Hist!$F$18)/(FS_Hist!$F$8)*DaysYr) -> 213.63928 | D17: =IF((FS_Hist!$G$8)=0,"n/a",(FS_Hist!$G$18)/(FS_Hist!$G$8)*DaysYr) -> 90.861235 | E17: =IF((FS_Hist!$H$8)=0,"n/a",(FS_Hist!$H$18)/(FS_Hist!$H$8)*DaysYr) -> 56.524134 | F17: =IF(COUNT(C17:E17)=0,0,AVERAGE(C17:E17)) -> 120.34155
A18: 재고 회전일수(매출원가 기준) | C18: =IF((FS_Hist!$F$9)=0,"n/a",(FS_Hist!$F$19)/(FS_Hist!$F$9)*DaysYr) -> 3.6566367 | D18: =IF((FS_Hist!$G$9)=0,"n/a",(FS_Hist!$G$19)/(FS_Hist!$G$9)*DaysYr) -> 3.7681029 | E18: =IF((FS_Hist!$H$9)=0,"n/a",(FS_Hist!$H$19)/(FS_Hist!$H$9)*DaysYr) -> 0 | F18: =IF(COUNT(C18:E18)=0,0,AVERAGE(C18:E18)) -> 2.4749132
A19: 매입채무 회전일수(매출원가 기준) | C19: =IF((FS_Hist!$F$9)=0,"n/a",(FS_Hist!$F$20)/(FS_Hist!$F$9)*DaysYr) -> 9957.9163 | D19: =IF((FS_Hist!$G$9)=0,"n/a",(FS_Hist!$G$20)/(FS_Hist!$G$9)*DaysYr) -> 3120.6809 | E19: =IF((FS_Hist!$H$9)=0,"n/a",(FS_Hist!$H$20)/(FS_Hist!$H$9)*DaysYr) -> 1590.2875 | F19: =IF(COUNT(C19:E19)=0,0,AVERAGE(C19:E19)) -> 4889.6282
A20: 기초 투하자본(전년 말) | C20: =FS_Hist!$E$18+FS_Hist!$E$19-FS_Hist!$E$20+FS_Hist!$E$21+FS_Hist!$E$22+FS_Hist!$E$23 -> 3743.7428 | D20: =FS_Hist!$F$18+FS_Hist!$F$19-FS_Hist!$F$20+FS_Hist!$F$21+FS_Hist!$F$22+FS_Hist!$F$23 -> 308.7531 | E20: =FS_Hist!$G$18+FS_Hist!$G$19-FS_Hist!$G$20+FS_Hist!$G$21+FS_Hist!$G$22+FS_Hist!$G$23 -> 813.92134
A21: NOPAT = 영업이익 − 누진 세금 | C21: =FS_Hist!$F$10-IF(FS_Hist!$F$10>0,SUMPRODUCT((FS_Hist!$F$10>TaxFrom)*(FS_Hist!$F$10-TaxFrom)*TaxDRate),0) -> 1155.86 | D21: =FS_Hist!$G$10-IF(FS_Hist!$G$10>0,SUMPRODUCT((FS_Hist!$G$10>TaxFrom)*(FS_Hist!$G$10-TaxFrom)*TaxDRate),0) -> 66.94595 | E21: =FS_Hist!$H$10-IF(FS_Hist!$H$10>0,SUMPRODUCT((FS_Hist!$H$10>TaxFrom)*(FS_Hist!$H$10-TaxFrom)*TaxDRate),0) -> -1794.8232
A22: ROIC(기초 투하자본 > 0일 때) | C22: =IF(C20>0,C21/C20,"") -> 0.30874451 | D22: =IF(D20>0,D21/D20,"") -> 0.21682681 | E22: =IF(E20>0,E21/E20,"") -> -2.2051556 | F22: =AVERAGE(C22:E22) -> -0.55986143 | G22: RONIC 상한(사전 고정)
A24: 매출 5년 CAGR(FY2020 → FY2025) | B24: % | C24: =(FS_Hist!$H$8/FS_Hist!$C$8)^(1/(2025-2020))-1 -> 0.0081194842
A25: 순운전자본(기초, 2026-06-30) | B25: 백만원 | C25: =FS_Hist!$J$18+FS_Hist!$J$19-FS_Hist!$J$20 -> 304.03032 | D25: 매출채권 + 재고 − 매입채무
A26: 2026 상반기 매출(연결) | B26: 백만원 | C26: =FS_Hist!$J$8 -> 1699.4526
A27: 2026 상반기 영업이익(연결) | B27: 백만원 | C27: =FS_Hist!$J$10 -> -259.27283
A28: FY2025 매출(연결) | B28: 백만원 | C28: =FS_Hist!$H$8 -> 3686.9784
A29: LTM 세전이익(세후 Kd 한계세율 기준) | B29: 백만원 | C29: =FS_Hist!$H$11+FS_Hist!$J$11-FS_Hist!$I$11 -> -4703.86
A31: 기본 경로 v2 — 5년 이익률 중앙값, 피어 쪽 수렴, 성장률 혼합(사전 고정 91a84dd)
A32: 영업이익률 FY2021~2025(매출 > 0인 해) | C32: =IF(FS_Hist!$D$8>0,FS_Hist!$D$10/FS_Hist!$D$8,"n/a") -> 0.4136115 | D32: =IF(FS_Hist!$E$8>0,FS_Hist!$E$10/FS_Hist!$E$8,"n/a") -> -0.098104633 | E32: =IF(FS_Hist!$F$8>0,FS_Hist!$F$10/FS_Hist!$F$8,"n/a") -> 0.31979196 | F32: =IF(FS_Hist!$G$8>0,FS_Hist!$G$10/FS_Hist!$G$8,"n/a") -> 0.01454955 | G32: =IF(FS_Hist!$H$8>0,FS_Hist!$H$10/FS_Hist!$H$8,"n/a") -> -0.48680058
A33: 출발 정상 이익률 v2 = 중앙값(3년 이상), 아니면 3년 평균 | B33: % | C33: =IF(COUNT(C32:G32)>=3,MEDIAN(C32:G32),HistMargin) -> 0.01454955
A34: 2032년까지 피어 쪽 이동 폭 = 수렴 비율 × (피어 중앙값 − 출발) | B34: % | C34: =IF(ISNUMBER(PeerMarginV2),ConvShare*(PeerMarginV2-M0V2),0) -> 0.054500896 | D34: 체감·영구 구간 = 출발 + 이동 폭
A35: 출발 성장률 v2 = clip(가중 × CAGR + (1 − 가중) × 피어 성장률) | B35: % | C35: =MAX(ClipLo,MIN(ClipHi,IF(ISNUMBER(PeerGrowthV2),WOwn*CAGR+(1-WOwn)*PeerGrowthV2,CAGR))) -> 0.014420192
A37: 시나리오 파라미터 — Inputs 표 3 연결, '선택' 열 = INDEX(…, 선택 순번)
A38: 선택 순번 | B38: =MATCH(ScenSel,ScenNames,0) -> 2 | C38: 비관 | D38: 기본 | E38: 낙관 | F38: 선택
A39: 출발 성장률 이동 | C39: =Inputs!B120 -> -0.02 | D39: =Inputs!C120 -> 0 | E39: =Inputs!D120 -> 0.02 | F39: =IF(ISNUMBER(GrowthShiftOvr),GrowthShiftOvr,INDEX(C39:E39,ScenIdx)) -> 0
A40: 정상 이익률 이동 | C40: =Inputs!B121 -> -0.02 | D40: =Inputs!C121 -> 0 | E40: =Inputs!D121 -> 0.02 | F40: =IF(ISNUMBER(MarginShiftOvr),MarginShiftOvr,INDEX(C40:E40,ScenIdx)) -> 0
A41: 출발 성장률 = v2 출발 성장률 + 이동 | C41: =G0Base+C39 -> -0.0055798084 | D41: =G0Base+D39 -> 0.014420192 | E41: =G0Base+E39 -> 0.034420192 | F41: =G0Base+F39 -> 0.014420192
A42: 출발 정상 영업이익률 = v2 중앙값 + 이동 | C42: =M0V2+C40 -> -0.0054504496 | D42: =M0V2+D40 -> 0.01454955 | E42: =M0V2+E40 -> 0.03454955 | F42: =M0V2+F40 -> 0.01454955
A43: 명시 마지막 연도 성장률 | C43: =C41+(GTermCfg-C41)*MIN(ExplicitEnd-YEAR(CfStart),FadeTo-YEAR(CfStart))/(FadeTo-YEAR(CfStart)) -> 0.02 | D43: =D41+(GTermCfg-D41)*MIN(ExplicitEnd-YEAR(CfStart),FadeTo-YEAR(CfStart))/(FadeTo-YEAR(CfStart)) -> 0.02 | E43: =E41+(GTermCfg-E41)*MIN(ExplicitEnd-YEAR(CfStart),FadeTo-YEAR(CfStart))/(FadeTo-YEAR(CfStart)) -> 0.02 | F43: =F41+(GTermCfg-F41)*MIN(ExplicitEnd-YEAR(CfStart),FadeTo-YEAR(CfStart))/(FadeTo-YEAR(CfStart)) -> 0.02
A44: 영구성장률(설정) | B44: % | C44: =GTermCfg -> 0.02
A45: 영구·체감 구간 g(데이터 표 입력 칸이 비면 시나리오 값) | B45: % | C45: =IF(ISNUMBER(GOvr),GOvr,GTerm_Sel) -> 0.02 | D45: Scenarios 시트의 데이터 표가 GOvr 칸에 값을 넣어 계산한다
...

Sheet WACC
A1: WACC — 피어 베타 → 할인율
A2: 원 β → Blume(0.67 β + 0.33) → Hamada 언레버(회사별 기간평균 D/E, t 22%) → 포함 피어 중앙값. 회귀 결과는 한국거래소 통계정보 기반
A5: 포함 피어 수 | B5: 곳 | C5: =BetaPubN -> 6
A6: βu(공개 모드 집계 입력) | C6: =BetaPubU -> 0.62399371 | D6: 엔진 βu 중앙값 | E6: 0.62399371
A7: R² 중앙값(포함 피어, 집계 입력) | C7: =BetaPubR2 -> 0.15
A8: 베타 신뢰성 경고 | C8: =IF(ISNUMBER(BetaR2Median),IF(BetaR2Median<BetaR2Warn,"경고: 회귀 베타 신뢰 낮음(R² 중앙값 "&TEXT(BetaR2Median,"0.00")&" < "&TEXT(BetaR2Warn,"0.00")&")","경고 없음"),"공개 모드: 피어 부족 — R² 중앙값 표시 안 함") -> 경고 없음 | D8: 표시만(경로 불변, common_rules)
A10: 할인율 (선택한 SRP)
A11: Rf(Inputs 'Rf 만기 선택', 데이터 표 입력 칸이 비면) | C11: =IF(ISNUMBER(RfOvr),RfOvr,IF(RfTenor=10,Rf_10Y,Rf_5Y)) -> 0.04203
A12: MRP(데이터 표 입력 칸이 비면 Inputs 값) | C12: =IF(ISNUMBER(MrpOvr),MrpOvr,MRP) -> 0.08
A13: SRP(데이터 표 입력 칸이 비면 선택 값) | C13: =IF(ISNUMBER(SrpOvr),SrpOvr,SRP_Sel) -> 0
A14: βu | C14: =BetaU -> 0.62399371
A15: 목표 D/E | B15: 배 | C15: =DE_Target -> 0.0042596555
A16: βL = βu × (1 + (1 − t) × D/E) | C16: =BetaU*(1+(1-T_Hamada)*DE_Target) -> 0.62606695
A17: Ke = Rf + βL × MRP + SRP | C17: =Rf+BetaL*MRP_Eff+SRP_Eff -> 0.092115356
A18: 한계세율 기준: 연결 LTM 세전이익 | B18: 백만원 | C18: =PretaxLTM -> -4703.86 | D18: company_dcf.discount_rate
A19: 한계세율(세후 Kd) | B19: % | C19: =INDEX(TaxRate,COUNTIF(TaxTo,"<"&EbitEnd)+1) -> 0.11
A20: 실제 가중 약정이자율(Inputs 표 5) | B20: % | C20: =IF(SUM(BorrowAmt)>0,SUMPRODUCT(BorrowRate,BorrowAmt)/SUM(BorrowAmt),0) -> 0 | D20: 등급 A+~BBB+일 때만 규칙에 쓰인다 | E20: =IF(OR(RatingIdx=0,RatingIdx<=MATCH("AA-",RatingScale,0),RatingIdx>MATCH("BBB+",RatingScale,0)),"미사용(규칙상: "&IF(RatingIdx=0,"무등급 → BBB- 3년","등급 구간 밖")&")","사용") -> 미사용(규칙상: 무등급 → BBB- 3년)
A21: 등급 순번(빈칸 = 무등급 0) | C21: =IF(Rating="",0,MATCH(Rating,RatingScale,0)) -> 0
A22: 규칙 Kd(하한 전) | B22: % | C22: =IF(RatingIdx=0,Kd_BBB,IF(RatingIdx<=MATCH("AA-",RatingScale,0),Kd_AA,IF(RatingIdx<=MATCH("BBB+",RatingScale,0),MAX(N(Kd_Actual),Kd_AA),Kd_BBB))) -> 0.10506
A23: 세전 Kd = max(규칙 Kd, Rf) | B23: % | C23: =MAX(C22,Rf) -> 0.10506
A24: 세후 Kd | B24: % | C24: =Kd_Pre*(1-T_Kd) -> 0.0935034 | E24: =IF(DE_Target=0,"미사용(D/E 0 → WACC에 Kd 반영 안 됨)","사용(D/V "&TEXT(DE_Target/(1+DE_Target),"0.0%")&")") -> 사용(D/V 0.4%)
A25: D/V = D/E ÷ (1 + D/E) | B25: % | C25: =DE_Target/(1+DE_Target) -> 0.0042415878
A26: WACC(계산) = E/V × Ke + D/V × Kd × (1 − t) | B26: % | C26: =(1-WD)*Ke+WD*Kd_AT -> 0.092121243
A27: WACC(모델 사용, 데이터 표 입력 칸이 비면 계산값) | B27: % | C27: =IF(ISNUMBER(WaccOvr),WaccOvr,WaccCalc) -> 0.092121243 | D27: Scenarios 시트 WACC × g 데이터 표가 WaccOvr 칸에 값을 넣어 계산
A28: Kd 규칙(공통 규칙, 위 순서): 무등급 → BBB- 3년 / AA- 이상 → AA- 3년 / A+~BBB+ → max(실제 가중, AA- 3년) / BBB 이하 → BBB- 3년, 하한 Rf
A30: SRP 열별 WACC(같은 βu·D/E)
A31: SRP 열 1 | B31: % | C31: =(1-WD)*(Rf+BetaL*MRP+SRP_1)+WD*Kd_AT -> 0.092121243
A32: SRP 열 2 | B32: % | C32: =(1-WD)*(Rf+BetaL*MRP+SRP_2)+WD*Kd_AT -> 0.10207883
A33: SRP 열 3 | B33: % | C33: =(1-WD)*(Rf+BetaL*MRP+SRP_3)+WD*Kd_AT -> 0.11203641

Sheet DCF
A1: DCF — 할인·영구가치·EV (선택한 시나리오·SRP)
A2: 할인 기준일 6/30(재무상태표) → mid-year 할인 → EV를 평가기준일 9/30로 이월. 순현금은 6/30 장부(이월 안 함)
A4: 기간 | D4: =Forecast!D47 -> 2H26 | E4: =Forecast!E47 -> 2027 | F4: =Forecast!F47 -> 2028 | G4: =Forecast!G47 -> 2029 | H4: =Forecast!H47 -> 2030 | I4: =Forecast!I47 -> 2031 | J4: =Forecast!J47 -> 2032 | K4: =Forecast!K47 -> 2033 | ... R4: =Forecast!R47 -> 2040
A5: 연도 | D5: =Forecast!D49 -> 2026 | E5: =Forecast!E49 -> 2027 | F5: =Forecast!F49 -> 2028 | G5: =Forecast!G49 -> 2029 | H5: =Forecast!H49 -> 2030 | I5: =Forecast!I49 -> 2031 | J5: =Forecast!J49 -> 2032 | K5: =Forecast!K49 -> 2033 | ... R5: =Forecast!R49 -> 2040
A6: 기간 비율 | D6: =Forecast!D53 -> 0.50410959 | E6: =Forecast!E53 -> 1 | F6: =Forecast!F53 -> 1.0027397 | G6: =Forecast!G53 -> 1 | H6: =Forecast!H53 -> 1 | I6: =Forecast!I53 -> 1 | J6: =Forecast!J53 -> 1.0027397 | K6: =Forecast!K53 -> 1 | ... R6: =Forecast!R53 -> 1.0027397
A7: 종료일 | D7: =Forecast!D52 -> 46387 | E7: =Forecast!E52 -> 46752 | F7: =Forecast!F52 -> 47118 | G7: =Forecast!G52 -> 47483 | H7: =Forecast!H52 -> 47848 | I7: =Forecast!I52 -> 48213 | J7: =Forecast!J52 -> 48579 | K7: =Forecast!K52 -> 48944 | ... R7: =Forecast!R52 -> 51501
A8: FCFF | B8: 백만원 | D8: =Forecast!D69 -> 210.30621 | E8: =Forecast!E69 -> 119.57418 | F8: =Forecast!F69 -> 152.67171 | G8: =Forecast!G69 -> 187.12988 | H8: =Forecast!H69 -> 222.64865 | I8: =Forecast!I69 -> 255.67959 | J8: =Forecast!J69 -> 289.95151 | K8: =Forecast!K69 -> 196.89752 | ... R8: =Forecast!R69 -> 223.61244
A9: 기간 말까지 연수(할인 기준일부터) | B9: 년 | D9: =(D7-DiscDate)/DaysYr -> 0.50410959 | E9: =(E7-DiscDate)/DaysYr -> 1.5041096 | F9: =(F7-DiscDate)/DaysYr -> 2.5068493 | G9: =(G7-DiscDate)/DaysYr -> 3.5068493 | H9: =(H7-DiscDate)/DaysYr -> 4.5068493 | I9: =(I7-DiscDate)/DaysYr -> 5.5068493 | J9: =(J7-DiscDate)/DaysYr -> 6.509589 | K9: =(K7-DiscDate)/DaysYr -> 7.509589 | ... R9: =(R7-DiscDate)/DaysYr -> 14.515068
A10: 할인 연수(mid-year면 기간 중앙) | B10: 년 | D10: =D9-IF(MidYear=1,D6/2,0) -> 0.25205479 | E10: =E9-IF(MidYear=1,E6/2,0) -> 1.0041096 | F10: =F9-IF(MidYear=1,F6/2,0) -> 2.0054795 | G10: =G9-IF(MidYear=1,G6/2,0) -> 3.0068493 | H10: =H9-IF(MidYear=1,H6/2,0) -> 4.0068493 | I10: =I9-IF(MidYear=1,I6/2,0) -> 5.0068493 | J10: =J9-IF(MidYear=1,J6/2,0) -> 6.0082192 | K10: =K9-IF(MidYear=1,K6/2,0) -> 7.009589 | ... R10: =R9-IF(MidYear=1,R6/2,0) -> 14.013699
A11: 할인계수 (1 + WACC)^−t | D11: =(1+WACC)^(-D10) -> 0.97803331 | E11: =(1+WACC)^(-E10) -> 0.91531771 | F11: =(1+WACC)^(-F10) -> 0.83800882 | G11: =(1+WACC)^(-G10) -> 0.76722952 | H11: =(1+WACC)^(-H10) -> 0.70251314 | I11: =(1+WACC)^(-I10) -> 0.64325563 | J11: =(1+WACC)^(-J10) -> 0.58892544 | K11: =(1+WACC)^(-K10) -> 0.53918405 | ... R11: =(1+WACC)^(-R10) -> 0.29085985
A12: 현재가치(6/30) | B12: 백만원 | D12: =D8*D11 -> 205.68648 | E12: =E8*E11 -> 109.44836 | F12: =F8*F11 -> 127.94023 | G12: =G8*G11 -> 143.57157 | H12: =H8*H11 -> 156.4136 | I12: =I8*I11 -> 164.46734 | J12: =J8*J11 -> 170.75982 | K12: =K8*K11 -> 106.164 | ... R12: =R8*R11 -> 65.039882
A14: RONIC — 2027~명시 마지막 연도 증분 ROIC (P3-B2 규칙, P3-C3 출발점)
A15: FY2026 EBIT(정상 = FY2026 매출 × 정상 이익률) | B15: 백만원 | C15: =Forecast!D56*Margin_Sel -> 54.417432
A16: NOPAT FY2026 (normal 규칙) | B16: 백만원 | C16: =C15-IF(C15>0,SUMPRODUCT((C15>TaxFrom)*(C15-TaxFrom)*TaxDRate),0) -> 48.431515
A17: FY2026 EBIT(혼합 = 1H 실적 + 2H 정상) | B17: 백만원 | C17: =Forecast!D59 -> -229.58167
A18: NOPAT FY2026 (mixed 규칙) | B18: 백만원 | C18: =C17-IF(C17>0,SUMPRODUCT((C17>TaxFrom)*(C17-TaxFrom)*TaxDRate),0) -> -229.58167
A19: 출발 NOPAT(선택 규칙) | B19: 백만원 | C19: =IF(RonicStart="normal",C16,C18) -> 48.431515 | D19: Inputs의 RONIC 출발점 규칙
A20: 명시 마지막 연도 EBIT | B20: 백만원 | C20: =INDEX(Forecast!$D$58:$R$58,MATCH(ExplicitEnd,Forecast!$D$49:$R$49,0)) -> 288.4607
A21: NOPAT | B21: 백만원 | C21: =C20-IF(C20>0,SUMPRODUCT((C20>TaxFrom)*(C20-TaxFrom)*TaxDRate),0) -> 246.99934
A22: 누적 재투자 Σ(CAPEX − D&A + ΔNWC), 2027~명시 끝 | B22: 백만원 | C22: =SUMPRODUCT((Forecast!$D$48:$R$48>1)*Forecast!$D$54:$R$54*(Forecast!$D$61:$R$61-Forecast!$D$60:$R$60+Forecast!$D$63:$R$63)) -> -246.83057
A23: 증분 ROIC(계산값) | C23: =IF(C22>0,(C21-C19)/C22,0) -> 0
A24: RONIC(적용) | C24: =IF(C22<=0,WACC,IF(C23<WACC,WACC,IF(C23>RonicCap,MAX(RonicCap,WACC),C23))) -> 0.092121243 | D24: 재투자 ≤ 0이면 WACC, 그 밖은 [WACC, 과거 3년 ROIC]로 자름(사전 고정); 과거 ROIC < WACC면 WACC(하한 우선, P7-X2b)
A25: 대체 여부 | C25: =IF(C22<=0,"재투자 ≤ 0 → WACC",IF(C23<WACC,"계산값 < WACC → 하한",IF(C23>RonicCap,IF(RonicCap<WACC,"과거 ROIC < WACC → WACC(하한 우선)","계산값 > 상한(과거 ROIC)"),"계산값 사용"))) -> 재투자 ≤ 0 → WACC
A27: 영구가치 (가치동인: FCF = NOPAT × (1 − g ÷ RONIC))
A28: 마지막 체감 연도 매출 | B28: 백만원 | C28: =Forecast!$R$57 -> 4894.6488
A29: 마지막 체감 연도 EBIT | B29: 백만원 | C29: =Forecast!$R$58 -> 337.97768
A30: 다음 해 매출 = 매출 × (1 + g) | B30: 백만원 | C30: =C28*(1+GEff) -> 4992.5417
A31: 다음 해 EBIT | B31: 백만원 | C31: =C30*(Margin_Sel+MarginConvAmt) -> 344.73723
A32: 다음 해 NOPAT | B32: 백만원 | C32: =C31-IF(C31>0,SUMPRODUCT((C31>TaxFrom)*(C31-TaxFrom)*TaxDRate),0) -> 290.89504
A33: 다음 해 FCF = NOPAT × (1 − g ÷ RONIC) | B33: 백만원 | C33: =C32*(1-GEff/RONIC) -> 227.74022
A34: 영구가치 TV(Gordon, mid-year면 × (1+WACC)^0.5) | B34: 백만원 | C34: =C33/(WACC-GEff)*IF(MidYear=1,(1+WACC)^0.5,1) -> 3299.9849
A35: 마지막 기간 말까지 연수 | C35: =R9 -> 14.515068
A36: 영구가치 현재가치 | B36: 백만원 | C36: =C34*(1+WACC)^(-C35) -> 918.34926
A37: 명시·체감 FCFF 현재가치 합 | B37: 백만원 | C37: =SUM(D12:R12) -> 1751.5871
A38: EV(할인 기준일 6/30) | B38: 백만원 | C38: =C37+C36 -> 2669.9363
A39: 이월 일수(평가기준일 − 할인 기준일) | C39: =ValDate-DiscDate -> 92
A40: EV(평가기준일, × (1+WACC)^(일수 ÷ 365)) | B40: 백만원 | C40: =C38*(1+WACC)^(C39/DaysYr) -> 2729.9032
A41: 영구가치 비중(PV TV ÷ EV) | C41: =C36/C38 -> 0.34395924
A42: 명시 마지막 연도 D&A | B42: 백만원 | C42: =INDEX(Forecast!$D$60:$R$60,MATCH(ExplicitEnd,Forecast!$D$49:$R$49,0)) -> 100.95323
A43: 명시 마지막 연도 매출 | B43: 백만원 | C43: =INDEX(Forecast!$D$57:$R$57,MATCH(ExplicitEnd,Forecast!$D$49:$R$49,0)) -> 4177.5356
...

Sheet Bridge
A1: Bridge — EV → 주식가치 → 주당 (연결 DCF − 비지배지분)
A2: 주식가치 = EV − 순차입금(차입금 + 리스부채 − 현금성) + 비영업자산 − 비지배지분(장부). 현금성·비영업은 FS_Hist 줄 분류(peer_p3 규칙)
A4: EV(평가기준일) | B4: 백만원 | C4: =EV_930 -> 2729.9032 | D4: DCF 시트
A5: 총차입금(차입금·사채) | B5: 백만원 | C5: =FS_Hist!$J$24 -> 0 | D5: 2026-06-30 연결
A6: 리스부채(IFRS 16) | B6: 백만원 | C6: =FS_Hist!$J$25 -> 55.459414 | D6: WACC D/E와 같은 정의
A7: 현금성(유동 금융자산 줄 합계) | B7: 백만원 | C7: =SUMIFS(BsAmt,BsClass,"cash_like") -> 1111.4503 | D7: FS_Hist 분류 cash_like
A8: 순차입금 = 차입금 + 리스 − 현금성 | B8: 백만원 | C8: =C5+C6-C7 -> -1055.9909
A9: 비영업자산(비유동 금융자산·관계기업 줄 합계) + SOTP 종속회사 가치 | B9: 백만원 | C9: =SUMIFS(BsAmt,BsClass,"non_operating")+SotpRemainder+SotpListed*(1-SubDiscount)+SotpUnlisted+AssocLines+AssocValue-AssocReplaced -> 235050.34 | D9: FS_Hist 분류 non_operating + 아래 SOTP 행(종속 줄은 빼고 바꿔 넣음)
A10: 참고: '기타금융자산' 줄 합계(유동 + 비유동) | B10: 백만원 | C10: =SUMPRODUCT(ISNUMBER(SEARCH("기타금융자산",BsName))*BsAmt) -> 0 | D10: 현금성·비영업 안에 포함된 금액
A11: SOTP: 별도 재무상태표 '종속' 투자 줄(비영업에서 제외) | B11: 백만원 | C11: =SUMIFS(BsAmt,BsClass,"sub_inv") -> 70894.006 | D11: FS_Hist 분류 sub_inv
A12: SOTP: 그중 연결 범위 피투자회사 장부가(출자현황) | B12: 백만원 | C12: =SUM(SubBook) -> 51166 | D12: Inputs 표 10
A13: SOTP: 합친 줄의 관계기업 몫 = max(줄 − 장부, 0) | B13: 백만원 | C13: =MAX(C11-C12,0) -> 19728.006 | D13: 장부가 유지
A14: SOTP: 상장 종속회사 지분 시가 = 보유 주식수 × 종가 | B14: 백만원 | C14: =SUMPRODUCT(SubShares,SubClose,SubListedDirect)/MnToWon -> 142764 | D14: 직접 보유분만, 한국거래소 통계정보 종가
A15: SOTP: 상장 지분 할인율 | C15: =SubDiscount -> 0.3 | D15: 기본 0%, 민감도 30%·50%
A16: SOTP: 비상장 종속회사 장부가 | B16: 백만원 | C16: =SUMPRODUCT(SubBook,SubUnlisted) -> 29988 | D16: Inputs 표 10
A17: 상장 관계기업: 관계기업·공동기업·지분법 줄(비영업, 장부) | B17: 백만원 | C17: =SUMIFS(BsAmt,BsClass,"nonop_assoc") -> 13228.925 | D17: FS_Hist 분류 nonop_assoc
A18: 상장 관계기업 지분 시가 × (1 − 할인) | B18: 백만원 | C18: =SUMPRODUCT(AssocShares,AssocClose)/MnToWon*(1-AssocDiscount) -> 51936 | D18: Inputs 표 11, 한국거래소 통계정보 종가
A19: 빼는 장부 = MIN(관계기업 줄, Σ 관계기업 장부) (줄이 없으면 SOTP 나머지에서) | B19: 백만원 | C19: =IF(AssocLines>0,MIN(AssocLines,SUM(AssocBook)),MIN(SotpRemainder,SUM(AssocBook))) -> 12262 | D19: 이중 계산 방지(관계기업 장부를 시가로 바꿈)
A20: 비지배지분(장부) | B20: 백만원 | C20: =FS_Hist!$J$26 -> 0 | D20: 상장 종속회사 없음 → 장부
A21: 주식가치 | B21: 백만원 | C21: =C4-C8+C9-C20 -> 238836.23
A22: EV 밖 항목 합계(시나리오·SRP와 무관) | B22: 백만원 | C22: =C21-C4 -> 236106.33 | D22: Scen_Calc·Peers가 같은 값을 쓴다
A23: 지분법 방식 배수(PER·PBR)에 더할 항목 | B23: 백만원 | C23: =0 -> 0 | D23: 연결 구조: 없음
A24: 유통주식수 = (보통주 + 우선주) − 자기주식 | B24: 주 | C24: =(CommonIssued-CommonTreasury)+(PrefIssued-PrefTreasury) -> 27345997 | D24: 우선주를 보통주와 같은 청구권으로 본다(⚠️)
A25: 주당 가치(원, Gordon) | B25: 원 | C25: =C21*MnToWon/Shares -> 8733.8645 | D25: 가정 하의 추정 내재가치(예시)
A26: 기준일 종가(보통주) 대비 | C26: =PerShare/Close-1 -> -0.56330678 | D26: 가정 차이 표시(판단 아님)
A27: 주식가치(Exit 영구가치) | B27: 백만원 | C27: =IF(ISNUMBER(EVExit_930),EVExit_930+BridgeAdj,"N/M") -> N/M
A28: 주당 가치(원, Exit) | B28: 원 | C28: =IF(ISNUMBER(C27),C27*MnToWon/Shares,"N/M") -> N/M
A29: 참고: 순자산가치(지배주주지분 장부, 없으면 자본총계 − 비지배, 주당 원) | B29: 원 | C29: =IF(FS_Hist!$J$27<>0,FS_Hist!$J$27,FS_Hist!$J$28-FS_Hist!$J$26)*MnToWon/Shares -> 4357.6355 | D29: 자산가치 접근(재평가 없음, 장부 그대로) — 03 문서 3-2
A31: 구조 판단 규칙 (config/valuation_rules.yaml structure)
A32: 시장 주식가치(보통주 + 우선주) | B32: 백만원 | C32: =Close*(CommonIssued-CommonTreasury+PrefIssued-PrefTreasury)/MnToWon -> 546919.94
A33: 비지배지분(상장 종속회사면 시가, 아니면 장부) | B33: 백만원 | C33: =IF(ListedSub=1,(1-Stake)*SubMC,C20) -> 0
A34: 비지배지분 ÷ 시장 주식가치 | C34: =C33/C32 -> 0
A35: 부문 이익률 차이 | C35: =SegMarginGap -> 0
A36: 부문 성장률 차이 | C36: =SegGrowthGap -> 0
A37: 규칙 판정 | C37: =IF(OR(C34>=NciShareMin,AND(ListedSub=1,OR(C35>=MarginGapMin,C36>=GrowthGapMin))),"sotp","consolidated") -> consolidated | D37: 비지배 ≥ 10% 또는 (상장 종속회사 + 이익률 차이 ≥ 5%p 또는 성장률 차이 ≥ 10%p) → SOTP

Sheet Peers
A1: Peers — 피어 배수 (LTM, 연결 브리지로 주당 환산)
A2: 배수 = EV(또는 시가총액) ÷ LTM 지표. 분모 ≤ 0이면 N/M, 배수 ≤ 0(음의 EV)은 통계에서 제외(엔진과 같음). 포함 = core+extended. 사분위 = QUARTILE.INC(pandas 선형 보간과 같음)
A3: 공개 모드: 피어별 시가총액·배수는 표시하지 않고 사분위 배수만 입력 칸(Inputs 표 P)으로 둔다
A5: 대상 LTM 지표 (연결, D&A는 점검 규칙 적용)
A6: 매출(연결 LTM) | B6: 백만원 | C6: =FS_Hist!$H$8+FS_Hist!$J$8-FS_Hist!$I$8 -> 2787.7031
A7: 영업이익(연결 LTM) | B7: 백만원 | C7: =FS_Hist!$H$10+FS_Hist!$J$10-FS_Hist!$I$10 -> -2826.6486
A8: D&A LTM(반기 값이 3개월로 보이면 FY 값, D&A/매출 1~20% 밖이면 N/M) | B8: 백만원 | C8: =IF(OR(FS_Hist!$H$17=0,FS_Hist!$H$16/FS_Hist!$H$8<DnaRatioLo,FS_Hist!$H$16/FS_Hist!$H$8>DnaRatioHi),"N/M",IF(AND(FS_Hist!$J$17<>0,FS_Hist!$I$17<>0,FS_Hist!$J$16/FS_Hist!$H$16>=DnaH1Lo,FS_Hist!$J$16/FS_Hist!$H$16<=DnaH1Hi,FS_Hist!$I$16/FS_Hist!$H$16>=DnaH1Lo,FS_Hist!$I$16/FS_Hist!$H$16<=DnaH1Hi),FS_Hist!$H$16+FS_Hist!$J$16-FS_Hist!$I$16,FS_Hist!$H$16)) -> 136.921
A9: EBITDA(LTM) | B9: 백만원 | C9: =IF(ISNUMBER(C8),C7+C8,"N/M") -> -2689.7276
A10: 지배주주순이익(LTM, 없으면 당기순이익) | B10: 백만원 | C10: =IF((FS_Hist!$H$13+FS_Hist!$J$13-FS_Hist!$I$13)<>0,FS_Hist!$H$13+FS_Hist!$J$13-FS_Hist!$I$13,FS_Hist!$H$12+FS_Hist!$J$12-FS_Hist!$I$12) -> -5457.3838
A11: 지배주주지분(6/30, 없으면 자본총계 − 비지배) | B11: 백만원 | C11: =IF(FS_Hist!$J$27<>0,FS_Hist!$J$27,FS_Hist!$J$28-FS_Hist!$J$26) -> 119163.89
A13: 배수 요약 → 주당 가치
A14: 배수 | C14: n | D14: q25 | E14: 중앙값 | F14: q75 | G14: 대상 지표 | H14: 주당 q25(원) | I14: 주당 중앙값(원) | J14: 주당 q75(원) | K14: 경고 | L14: 엔진 주당 q25 | M14: 엔진 주당 중앙값 | N14: 엔진 주당 q75
A15: EV/EBITDA | C15: =Inputs!B145 -> 3 | D15: =IF(OR(C15=0,NOT(ISNUMBER(Inputs!C145))),"N/M",Inputs!C145) -> N/M | E15: =IF(OR(C15=0,NOT(ISNUMBER(Inputs!D145))),"N/M",Inputs!D145) -> N/M | F15: =IF(OR(C15=0,NOT(ISNUMBER(Inputs!E145))),"N/M",Inputs!E145) -> N/M | G15: =C9 -> -2689.7276 | H15: =IF(OR(C15=0,NOT(ISNUMBER(D15)),NOT(ISNUMBER(G15)),N(G15)<=0),"N/M",(D15*G15+BridgeAdj)*MnToWon/Shares) -> N/M | I15: =IF(OR(C15=0,NOT(ISNUMBER(E15)),NOT(ISNUMBER(G15)),N(G15)<=0),"N/M",(E15*G15+BridgeAdj)*MnToWon/Shares) -> N/M | J15: =IF(OR(C15=0,NOT(ISNUMBER(F15)),NOT(ISNUMBER(G15)),N(G15)<=0),"N/M",(F15*G15+BridgeAdj)*MnToWon/Shares) -> N/M | K15: =IF(C15<PeerNWarn,"n<"&PeerNWarn,"") -> n<5 | L15: n/a | M15: n/a | N15: n/a
A16: EV/EBITDA(보완 전) | C16: =Inputs!B146 -> 3 | D16: =IF(OR(C16=0,NOT(ISNUMBER(Inputs!C146))),"N/M",Inputs!C146) -> N/M | E16: =IF(OR(C16=0,NOT(ISNUMBER(Inputs!D146))),"N/M",Inputs!D146) -> N/M | F16: =IF(OR(C16=0,NOT(ISNUMBER(Inputs!E146))),"N/M",Inputs!E146) -> N/M | G16: =C9 -> -2689.7276 | H16: =IF(OR(C16=0,NOT(ISNUMBER(D16)),NOT(ISNUMBER(G16)),N(G16)<=0),"N/M",(D16*G16+BridgeAdj)*MnToWon/Shares) -> N/M | I16: =IF(OR(C16=0,NOT(ISNUMBER(E16)),NOT(ISNUMBER(G16)),N(G16)<=0),"N/M",(E16*G16+BridgeAdj)*MnToWon/Shares) -> N/M | J16: =IF(OR(C16=0,NOT(ISNUMBER(F16)),NOT(ISNUMBER(G16)),N(G16)<=0),"N/M",(F16*G16+BridgeAdj)*MnToWon/Shares) -> N/M | K16: =IF(C16<PeerNWarn,"n<"&PeerNWarn,"") -> n<5
A17: EV/Sales | C17: =Inputs!B147 -> 3 | D17: =IF(OR(C17=0,NOT(ISNUMBER(Inputs!C147))),"N/M",Inputs!C147) -> N/M | E17: =IF(OR(C17=0,NOT(ISNUMBER(Inputs!D147))),"N/M",Inputs!D147) -> N/M | F17: =IF(OR(C17=0,NOT(ISNUMBER(Inputs!E147))),"N/M",Inputs!E147) -> N/M | G17: =C6 -> 2787.7031 | H17: =IF(OR(C17=0,NOT(ISNUMBER(D17)),NOT(ISNUMBER(G17)),N(G17)<=0),"N/M",(D17*G17+BridgeAdj)*MnToWon/Shares) -> N/M | I17: =IF(OR(C17=0,NOT(ISNUMBER(E17)),NOT(ISNUMBER(G17)),N(G17)<=0),"N/M",(E17*G17+BridgeAdj)*MnToWon/Shares) -> N/M | J17: =IF(OR(C17=0,NOT(ISNUMBER(F17)),NOT(ISNUMBER(G17)),N(G17)<=0),"N/M",(F17*G17+BridgeAdj)*MnToWon/Shares) -> N/M | K17: =IF(C17<PeerNWarn,"n<"&PeerNWarn,"") -> n<5 | L17: n/a | M17: n/a | N17: n/a
A18: PBR | C18: =Inputs!B148 -> 6 | D18: =IF(OR(C18=0,NOT(ISNUMBER(Inputs!C148))),"N/M",Inputs!C148) -> 0.46649647 | E18: =IF(OR(C18=0,NOT(ISNUMBER(Inputs!D148))),"N/M",Inputs!D148) -> 0.58888537 | F18: =IF(OR(C18=0,NOT(ISNUMBER(Inputs!E148))),"N/M",Inputs!E148) -> 0.96479007 | G18: =C11 -> 119163.89 | H18: =IF(OR(C18=0,NOT(ISNUMBER(D18)),NOT(ISNUMBER(G18)),N(G18)<=0),"N/M",(D18*G18+EqAddOn)*MnToWon/Shares) -> 2032.8216 | I18: =IF(OR(C18=0,NOT(ISNUMBER(E18)),NOT(ISNUMBER(G18)),N(G18)<=0),"N/M",(E18*G18+EqAddOn)*MnToWon/Shares) -> 2566.1478 | J18: =IF(OR(C18=0,NOT(ISNUMBER(F18)),NOT(ISNUMBER(G18)),N(G18)<=0),"N/M",(F18*G18+EqAddOn)*MnToWon/Shares) -> 4204.2034 | K18: =IF(C18<PeerNWarn,"n<"&PeerNWarn,"") | L18: 2032.8216 | M18: 2566.1478 | N18: 4204.2034
A19: PER | C19: =Inputs!B149 -> 5 | D19: =IF(OR(C19=0,NOT(ISNUMBER(Inputs!C149))),"N/M",Inputs!C149) -> 5.2590982 | E19: =IF(OR(C19=0,NOT(ISNUMBER(Inputs!D149))),"N/M",Inputs!D149) -> 7.6482179 | F19: =IF(OR(C19=0,NOT(ISNUMBER(Inputs!E149))),"N/M",Inputs!E149) -> 10.006508 | G19: =C10 -> -5457.3838 | H19: =IF(OR(C19=0,NOT(ISNUMBER(D19)),NOT(ISNUMBER(G19)),N(G19)<=0),"N/M",(D19*G19+EqAddOn)*MnToWon/Shares) -> N/M | I19: =IF(OR(C19=0,NOT(ISNUMBER(E19)),NOT(ISNUMBER(G19)),N(G19)<=0),"N/M",(E19*G19+EqAddOn)*MnToWon/Shares) -> N/M | J19: =IF(OR(C19=0,NOT(ISNUMBER(F19)),NOT(ISNUMBER(G19)),N(G19)<=0),"N/M",(F19*G19+EqAddOn)*MnToWon/Shares) -> N/M | K19: =IF(C19<PeerNWarn,"n<"&PeerNWarn,"") | L19: n/a | M19: n/a | N19: n/a
A20: EV 배수: 배수 × 대상 LTM 지표 + EV 밖 항목(− 순차입금 + 비영업 − 비지배, Bridge). PER × 지배순이익, PBR × 지배지분

Sheet Premium
A1: Premium — 지배 블록 1주당 가격 범위 (경영권 프리미엄 DB 집계값)
A2: 블록 1주당 = 20거래일 VWAP × (1 + 프리미엄). 지분 전체·DCF 가치에 (1+프리미엄)을 곱하지 않는다. 프리미엄 DB는 분위수·표본 수만
A4: D6 적용 규칙 (config/premium_p2c3.yaml application_rule, 사용자 결정 2026-10-03)
A5: 시총 백분위 | C5: =Prem_Pct -> 66.4
A6: 시장 | C6: =Prem_Market -> KOSDAQ
A7: 회귀 채택(CV 개선 ≥ 기준, 1=예) | C7: =IF(Prem_CV>=Prem_Thr,1,0) -> 1
A8: 회귀 q50 − 이웃 중앙값(절댓값) | C8: =ABS(Prem_REG_q50-Prem_NEI_q50) -> 0.0042705702
A9: 차이 경고(> 10%p, 1=예) | C9: =IF(ABS(Prem_REG_q50-Prem_NEI_q50)>Prem_GapWarn,1,0) -> 0
A10: method | C10: =IF(Prem_Market="KOSPI","neighbours",IF(Prem_Pct>=Prem_TopBand,"neighbours",IF(C7=1,IF(C9=1,"neighbours","regression"),"band_table"))) -> regression | D10: 엔진(predict.premium_range) | E10: regression
A11: 이유 | C11: =IF(Prem_Market="KOSPI","rule_market",IF(Prem_Pct>=Prem_TopBand,"rule_top_band",IF(C7=1,IF(C9=1,"warning","cv_adopted"),"cv_not_adopted"))) -> cv_adopted | E11: cv_adopted
A12: 순서: KOSPI → 이웃(rule_market) / KOSDAQ 백분위 ≥ 80 → 이웃(rule_top_band) / 회귀 채택 + 차이 경고 → 이웃(warning) / 회귀 채택 → 회귀(cv_adopted) / 미채택 → 구간 표(cv_not_adopted)
A14: 프리미엄 분위 | C14: q25 | D14: q50 | E14: q75 | F14: 표본 수
A15: 이웃 50건 | C15: =Prem_NEI_q25 -> -0.082132402 | D15: =Prem_NEI_q50 -> 0.084419618 | E15: =Prem_NEI_q75 -> 0.30876385 | F15: =Prem_NB_n -> 50
A16: 분위 회귀(참고, 항상 표시) | C16: =Prem_REG_q25 -> -0.080474082 | D16: =Prem_REG_q50 -> 0.080149048 | E16: =Prem_REG_q75 -> 0.36540326 | F16: ="회귀" -> 회귀
A17: 구간 표 P60-80 | C17: =Prem_BAN_q25 -> -0.092879496 | D17: =Prem_BAN_q50 -> 0.083969898 | E17: =Prem_BAN_q75 -> 0.40342333 | F17: =Prem_BAN_n -> 77
A18: 적용(D6 method) | C18: =IF(PremMethod="neighbours",C15,IF(PremMethod="regression",C16,C17)) -> -0.080474082 | D18: =IF(PremMethod="neighbours",D15,IF(PremMethod="regression",D16,D17)) -> 0.080149048 | E18: =IF(PremMethod="neighbours",E15,IF(PremMethod="regression",E16,E17)) -> 0.36540326 | F18: =IF(PremMethod="neighbours",F15,IF(PremMethod="band_table",F17,"회귀")) -> 회귀
A20: 블록 1주당 가격 (원)
A21: 20거래일 VWAP(평가기준일까지, 한국거래소 통계정보) | B21: 원 | C21: =VWAP20 -> 19800
A22: 기준일 종가 | B22: 원 | C22: =Close -> 20000
A23: 블록 1주당 q25 = VWAP × (1 + 프리미엄) | B23: 원 | C23: =IF(ISNUMBER(PremQ1),VWAP20*(1+PremQ1),"N/M") -> 18206.613 | D23: 엔진 | E23: 18206.613
A24: 블록 1주당 q50 = VWAP × (1 + 프리미엄) | B24: 원 | C24: =IF(ISNUMBER(PremQ2),VWAP20*(1+PremQ2),"N/M") -> 21386.951 | D24: 엔진 | E24: 21386.951
A25: 블록 1주당 q75 = VWAP × (1 + 프리미엄) | B25: 원 | C25: =IF(ISNUMBER(PremQ3),VWAP20*(1+PremQ3),"N/M") -> 27034.985 | D25: 엔진 | E25: 27034.985
A27: 상증법 최대주주 할증 비교 (⚠️ 원문 미확인, 중소·일정 중견기업 제외 가능)
A28: 할증 적용: VWAP × (1 + 할증률) | B28: 원 | C28: =VWAP20*(1+TaxPrem) -> 23760
A29: 할증 적용: 종가 × (1 + 할증률) | B29: 원 | C29: =Close*(1+TaxPrem) -> 24000
A30: 할증 제외(VWAP) | B30: 원 | C30: =VWAP20 -> 19800
A31: 세법 평가액은 평가기준일 전후 2개월 평균 종가가 원칙 — 여기서는 비교용 단순화
A33: 엔진 경고(predict.premium_range): 없음

Sheet Scenarios
A1: Scenarios — 시나리오 × SRP (가정 하의 추정 내재가치, 예시)
A2: A 표·C·D 데이터 표는 살아 있는 수식(Scen_Calc, 엑셀 What-If). 회색 표는 엔진 계산값(수식 아님) — 대조용
A4: A-1. 주당 가치(원, Gordon) — 살아 있는 수식
A5: 시나리오 \ SRP | B5: =SRP_1 -> 0 | C5: =SRP_2 -> 0.01 | D5: =SRP_3 -> 0.02 | F5: 기준일 종가 대비
A6: 비관 | B6: =Scen_Calc!$C$47 -> 8702.4406 | C6: =Scen_Calc!$C$60 -> 8695.7866 | D6: =Scen_Calc!$C$73 -> 8690.3282 | F6: =B6/Close-1 -> -0.56487797 | G6: =C6/Close-1 -> -0.56521067 | H6: =D6/Close-1 -> -0.56548359
A7: 기본 | B7: =Scen_Calc!$C$120 -> 8733.8645 | C7: =Scen_Calc!$C$133 -> 8724.325 | D7: =Scen_Calc!$C$146 -> 8716.4931 | F7: =B7/Close-1 -> -0.56330678 | G7: =C7/Close-1 -> -0.56378375 | H7: =D7/Close-1 -> -0.56417534
A8: 낙관 | B8: =Scen_Calc!$C$193 -> 8767.5065 | C8: =Scen_Calc!$C$206 -> 8754.833 | D8: =Scen_Calc!$C$219 -> 8744.4261 | F8: =B8/Close-1 -> -0.56162467 | G8: =C8/Close-1 -> -0.56225835 | H8: =D8/Close-1 -> -0.5627787
A10: A-2. WACC
A11: 시나리오 \ SRP | B11: =SRP_1 -> 0 | C11: =SRP_2 -> 0.01 | D11: =SRP_3 -> 0.02
A12: 비관 | B12: =Scen_Calc!$C$38 -> 0.092121243 | C12: =Scen_Calc!$C$51 -> 0.10207883 | D12: =Scen_Calc!$C$64 -> 0.11203641
A13: 기본 | B13: =Scen_Calc!$C$111 -> 0.092121243 | C13: =Scen_Calc!$C$124 -> 0.10207883 | D13: =Scen_Calc!$C$137 -> 0.11203641
A14: 낙관 | B14: =Scen_Calc!$C$184 -> 0.092121243 | C14: =Scen_Calc!$C$197 -> 0.10207883 | D14: =Scen_Calc!$C$210 -> 0.11203641
A16: A-3. RONIC(적용)
A17: 시나리오 \ SRP | B17: =SRP_1 -> 0 | C17: =SRP_2 -> 0.01 | D17: =SRP_3 -> 0.02
A18: 비관 | B18: =Scen_Calc!$C$39 -> 0.092121243 | C18: =Scen_Calc!$C$52 -> 0.10207883 | D18: =Scen_Calc!$C$65 -> 0.11203641
A19: 기본 | B19: =Scen_Calc!$C$112 -> 0.092121243 | C19: =Scen_Calc!$C$125 -> 0.10207883 | D19: =Scen_Calc!$C$138 -> 0.11203641
A20: 낙관 | B20: =Scen_Calc!$C$185 -> 0.092121243 | C20: =Scen_Calc!$C$198 -> 0.10207883 | D20: =Scen_Calc!$C$211 -> 0.11203641
A22: A-4. 영구가치 비중
A23: 시나리오 \ SRP | B23: =SRP_1 -> 0 | C23: =SRP_2 -> 0.01 | D23: =SRP_3 -> 0.02
A24: 비관 | B24: =Scen_Calc!$C$48 -> 0.35162596 | C24: =Scen_Calc!$C$61 -> 0.31024024 | D24: =Scen_Calc!$C$74 -> 0.27397114
A25: 기본 | B25: =Scen_Calc!$C$121 -> 0.34395924 | C25: =Scen_Calc!$C$134 -> 0.30290028 | D25: =Scen_Calc!$C$147 -> 0.26700511
A26: 낙관 | B26: =Scen_Calc!$C$194 -> 0.34149813 | C26: =Scen_Calc!$C$207 -> 0.30053198 | D26: =Scen_Calc!$C$220 -> 0.2647465
A28: 선택 칸(시나리오·SRP)의 표 값 | C28: =INDEX(ScenGridPS,ScenIdx,MATCH(SRP_Sel,SRP_List,0)) -> 8733.8645 | D28: = Bridge 주당 가치와 같아야 한다(Checks)
A30: B. 엔진 값(수식 아님) — rf_dcf2.value, P3-C3 규칙. Checks의 INFO 대조에 쓴다
A31: 엔진: 주당 가치(원, Gordon) | B31: 0 | C31: 0.01 | D31: 0.02
A32: 비관 | B32: 8702.4406 | C32: 8695.7866 | D32: 8690.3282
A33: 기본 | B33: 8733.8645 | C33: 8724.325 | D33: 8716.4931
A34: 낙관 | B34: 8767.5065 | C34: 8754.833 | D34: 8744.4261
A36: 엔진: WACC | B36: 0 | C36: 0.01 | D36: 0.02
A37: 비관 | B37: 0.092121243 | C37: 0.10207883 | D37: 0.11203641
A38: 기본 | B38: 0.092121243 | C38: 0.10207883 | D38: 0.11203641
A39: 낙관 | B39: 0.092121243 | C39: 0.10207883 | D39: 0.11203641
A41: 엔진: RONIC | B41: 0 | C41: 0.01 | D41: 0.02
A42: 비관 | B42: 0.092121243 | C42: 0.10207883 | D42: 0.11203641
A43: 기본 | B43: 0.092121243 | C43: 0.10207883 | D43: 0.11203641
A44: 낙관 | B44: 0.092121243 | C44: 0.10207883 | D44: 0.11203641
... A56: 엔진: 주당 가치(원, Exit) | B56: 0 | C56: 0.01 | D56: 0.02
A57: 비관 | B57: n/a | C57: n/a | D57: n/a
A58: 기본 | B58: n/a | C58: n/a | D58: n/a
A59: 낙관 | B59: n/a | C59: n/a | D59: n/a
...

Sheet Scen_Calc
A1: Scen_Calc — 시나리오 4 × SRP 3 (Forecast·DCF와 같은 수식, 시나리오 고정)
A2: Scenarios 시트 표의 계산. 할인 연수는 DCF 시트와 같은 행을 쓴다. 주식가치 = EV + Bridge의 EV 밖 항목
A4: 시나리오: 비관
A5: 기간 순번 | C5: 0 | D5: =C5+1 -> 1 | E5: =D5+1 -> 2 | F5: =E5+1 -> 3 | G5: =F5+1 -> 4 | H5: =G5+1 -> 5 | I5: =H5+1 -> 6 | J5: =I5+1 -> 7 | K5: =J5+1 -> 8 | ... R5: =Q5+1 -> 15
A6: 연도 | D6: =YEAR(CfStart)+D5-1 -> 2026 | E6: =YEAR(CfStart)+E5-1 -> 2027 | F6: =YEAR(CfStart)+F5-1 -> 2028 | G6: =YEAR(CfStart)+G5-1 -> 2029 | H6: =YEAR(CfStart)+H5-1 -> 2030 | I6: =YEAR(CfStart)+I5-1 -> 2031 | J6: =YEAR(CfStart)+J5-1 -> 2032 | K6: =YEAR(CfStart)+K5-1 -> 2033 | ... R6: =YEAR(CfStart)+R5-1 -> 2040
A7: 구간 | D7: =IF(D11=1,"명시","체감") -> 명시 | E7: =IF(E11=1,"명시","체감") -> 명시 | F7: =IF(F11=1,"명시","체감") -> 명시 | G7: =IF(G11=1,"명시","체감") -> 명시 | H7: =IF(H11=1,"명시","체감") -> 명시 | I7: =IF(I11=1,"명시","체감") -> 명시 | J7: =IF(J11=1,"명시","체감") -> 명시 | K7: =IF(K11=1,"명시","체감") -> 체감 | ... R7: =IF(R11=1,"명시","체감") -> 체감
A8: 시작일 | D8: =MAX(DATE(D6,1,1),CfStart) -> 46204 | E8: =MAX(DATE(E6,1,1),CfStart) -> 46388 | F8: =MAX(DATE(F6,1,1),CfStart) -> 46753 | G8: =MAX(DATE(G6,1,1),CfStart) -> 47119 | H8: =MAX(DATE(H6,1,1),CfStart) -> 47484 | I8: =MAX(DATE(I6,1,1),CfStart) -> 47849 | J8: =MAX(DATE(J6,1,1),CfStart) -> 48214 | K8: =MAX(DATE(K6,1,1),CfStart) -> 48580 | ... R8: =MAX(DATE(R6,1,1),CfStart) -> 51136
A9: 종료일 | D9: =DATE(D6,12,31) -> 46387 | E9: =DATE(E6,12,31) -> 46752 | F9: =DATE(F6,12,31) -> 47118 | G9: =DATE(G6,12,31) -> 47483 | H9: =DATE(H6,12,31) -> 47848 | I9: =DATE(I6,12,31) -> 48213 | J9: =DATE(J6,12,31) -> 48579 | K9: =DATE(K6,12,31) -> 48944 | ... R9: =DATE(R6,12,31) -> 51501
A10: 기간 비율(일수 ÷ 365) | D10: =(D9-D8+1)/DaysYr -> 0.50410959 | E10: =(E9-E8+1)/DaysYr -> 1 | F10: =(F9-F8+1)/DaysYr -> 1.0027397 | G10: =(G9-G8+1)/DaysYr -> 1 | H10: =(H9-H8+1)/DaysYr -> 1 | I10: =(I9-I8+1)/DaysYr -> 1 | J10: =(J9-J8+1)/DaysYr -> 1.0027397 | K10: =(K9-K8+1)/DaysYr -> 1 | ... R10: =(R9-R8+1)/DaysYr -> 1.0027397
A11: 명시 구간(1/0) | D11: =IF(D6<=ExplicitEnd,1,0) -> 1 | E11: =IF(E6<=ExplicitEnd,1,0) -> 1 | F11: =IF(F6<=ExplicitEnd,1,0) -> 1 | G11: =IF(G6<=ExplicitEnd,1,0) -> 1 | H11: =IF(H6<=ExplicitEnd,1,0) -> 1 | I11: =IF(I6<=ExplicitEnd,1,0) -> 1 | J11: =IF(J6<=ExplicitEnd,1,0) -> 1 | K11: =IF(K6<=ExplicitEnd,1,0) -> 0 | ... R11: =IF(R6<=ExplicitEnd,1,0) -> 0
A12: 매출 성장률 | B12: % | D12: =IF(D11=1,Forecast!$C$41+(GTermCfg-Forecast!$C$41)*MIN(D6-YEAR(CfStart),FadeTo-YEAR(CfStart))/(FadeTo-YEAR(CfStart)),Forecast!$C$43-(D6-ExplicitEnd)*(Forecast!$C$43-GTermCfg)/FadeYears) -> -0.0055798084 | E12: =IF(E11=1,Forecast!$C$41+(GTermCfg-Forecast!$C$41)*MIN(E6-YEAR(CfStart),FadeTo-YEAR(CfStart))/(FadeTo-YEAR(CfStart)),Forecast!$C$43-(E6-ExplicitEnd)*(Forecast!$C$43-GTermCfg)/FadeYears) -> 0.0008151437 | F12: =IF(F11=1,Forecast!$C$41+(GTermCfg-Forecast!$C$41)*MIN(F6-YEAR(CfStart),FadeTo-YEAR(CfStart))/(FadeTo-YEAR(CfStart)),Forecast!$C$43-(F6-ExplicitEnd)*(Forecast!$C$43-GTermCfg)/FadeYears) -> 0.0072100958 | G12: =IF(G11=1,Forecast!$C$41+(GTermCfg-Forecast!$C$41)*MIN(G6-YEAR(CfStart),FadeTo-YEAR(CfStart))/(FadeTo-YEAR(CfStart)),Forecast!$C$43-(G6-ExplicitEnd)*(Forecast!$C$43-GTermCfg)/FadeYears) -> 0.013605048 | H12: =IF(H11=1,Forecast!$C$41+(GTermCfg-Forecast!$C$41)*MIN(H6-YEAR(CfStart),FadeTo-YEAR(CfStart))/(FadeTo-YEAR(CfStart)),Forecast!$C$43-(H6-ExplicitEnd)*(Forecast!$C$43-GTermCfg)/FadeYears) -> 0.02 | I12: =IF(I11=1,Forecast!$C$41+(GTermCfg-Forecast!$C$41)*MIN(I6-YEAR(CfStart),FadeTo-YEAR(CfStart))/(FadeTo-YEAR(CfStart)),Forecast!$C$43-(I6-ExplicitEnd)*(Forecast!$C$43-GTermCfg)/FadeYears) -> 0.02 | J12: =IF(J11=1,Forecast!$C$41+(GTermCfg-Forecast!$C$41)*MIN(J6-YEAR(CfStart),FadeTo-YEAR(CfStart))/(FadeTo-YEAR(CfStart)),Forecast!$C$43-(J6-ExplicitEnd)*(Forecast!$C$43-GTermCfg)/FadeYears) -> 0.02 | K12: =IF(K11=1,Forecast!$C$41+(GTermCfg-Forecast!$C$41)*MIN(K6-YEAR(CfStart),FadeTo-YEAR(CfStart))/(FadeTo-YEAR(CfStart)),Forecast!$C$43-(K6-ExplicitEnd)*(Forecast!$C$43-GTermCfg)/FadeYears) -> 0.02 | ... R12: =IF(R11=1,Forecast!$C$41+(GTermCfg-Forecast!$C$41)*MIN(R6-YEAR(CfStart),FadeTo-YEAR(CfStart))/(FadeTo-YEAR(CfStart)),Forecast!$C$43-(R6-ExplicitEnd)*(Forecast!$C$43-GTermCfg)/FadeYears) -> 0.02
A13: 회계연도 매출 | B13: 백만원 | D13: =IF(D5=1,RevFY_Last*(1+D12),C13*(1+D12)) -> 3666.4057 | E13: =IF(E5=1,RevFY_Last*(1+E12),D13*(1+E12)) -> 3669.3944 | F13: =IF(F5=1,RevFY_Last*(1+F12),E13*(1+F12)) -> 3695.8511 | G13: =IF(G5=1,RevFY_Last*(1+G12),F13*(1+G12)) -> 3746.1333 | H13: =IF(H5=1,RevFY_Last*(1+H12),G13*(1+H12)) -> 3821.056 | I13: =IF(I5=1,RevFY_Last*(1+I12),H13*(1+I12)) -> 3897.4771 | J13: =IF(J5=1,RevFY_Last*(1+J12),I13*(1+J12)) -> 3975.4266 | K13: =IF(K5=1,RevFY_Last*(1+K12),J13*(1+K12)) -> 4054.9352 | ... R13: =IF(R5=1,RevFY_Last*(1+R12),Q13*(1+R12)) -> 4657.8459
A14: 기간 매출 | B14: 백만원 | D14: =IF(D5=1,D13-H1Rev,D13) -> 1966.9532 | E14: =IF(E5=1,E13-H1Rev,E13) -> 3669.3944 | F14: =IF(F5=1,F13-H1Rev,F13) -> 3695.8511 | G14: =IF(G5=1,G13-H1Rev,G13) -> 3746.1333 | H14: =IF(H5=1,H13-H1Rev,H13) -> 3821.056 | I14: =IF(I5=1,I13-H1Rev,I13) -> 3897.4771 | J14: =IF(J5=1,J13-H1Rev,J13) -> 3975.4266 | K14: =IF(K5=1,K13-H1Rev,K13) -> 4054.9352 | ... R14: =IF(R5=1,R13-H1Rev,R13) -> 4657.8459
A15: 영업이익(EBIT) | B15: 백만원 | D15: =D14*(Forecast!$C$42+MarginConvAmt*MIN((D6-YEAR(CfStart))/(ExplicitEnd-YEAR(CfStart)),1)) -> -10.720779 | E15: =E14*(Forecast!$C$42+MarginConvAmt*MIN((E6-YEAR(CfStart))/(ExplicitEnd-YEAR(CfStart)),1)) -> 13.331031 | F15: =F14*(Forecast!$C$42+MarginConvAmt*MIN((F6-YEAR(CfStart))/(ExplicitEnd-YEAR(CfStart)),1)) -> 46.998348 | G15: =G14*(Forecast!$C$42+MarginConvAmt*MIN((G6-YEAR(CfStart))/(ExplicitEnd-YEAR(CfStart)),1)) -> 81.665699 | H15: =H14*(Forecast!$C$42+MarginConvAmt*MIN((H6-YEAR(CfStart))/(ExplicitEnd-YEAR(CfStart)),1)) -> 118.00751 | I15: =I14*(Forecast!$C$42+MarginConvAmt*MIN((I6-YEAR(CfStart))/(ExplicitEnd-YEAR(CfStart)),1)) -> 155.77032 | J15: =J14*(Forecast!$C$42+MarginConvAmt*MIN((J6-YEAR(CfStart))/(ExplicitEnd-YEAR(CfStart)),1)) -> 194.99645 | K15: =K14*(Forecast!$C$42+MarginConvAmt*MIN((K6-YEAR(CfStart))/(ExplicitEnd-YEAR(CfStart)),1)) -> 198.89638 | ... R15: =R14*(Forecast!$C$42+MarginConvAmt*MIN((R6-YEAR(CfStart))/(ExplicitEnd-YEAR(CfStart)),1)) -> 228.46942
A16: 회계연도 영업이익(과세표준) | B16: 백만원 | D16: =IF(D5=1,H1Op+D15,D15) -> -269.99361 | E16: =IF(E5=1,H1Op+E15,E15) -> 13.331031 | F16: =IF(F5=1,H1Op+F15,F15) -> 46.998348 | G16: =IF(G5=1,H1Op+G15,G15) -> 81.665699 | H16: =IF(H5=1,H1Op+H15,H15) -> 118.00751 | I16: =IF(I5=1,H1Op+I15,I15) -> 155.77032 | J16: =IF(J5=1,H1Op+J15,J15) -> 194.99645 | K16: =IF(K5=1,H1Op+K15,K15) -> 198.89638 | ... R16: =IF(R5=1,H1Op+R15,R15) -> 228.46942
A17: D&A = 매출 × 과거 3년 D&A/매출 | B17: 백만원 | D17: =IF(D11=1,D14*DnaRatio,0) -> 47.532874 | E17: =IF(E11=1,E14*DnaRatio,0) -> 88.673622 | F17: =IF(F11=1,F14*DnaRatio,0) -> 89.312967 | G17: =IF(G11=1,G14*DnaRatio,0) -> 90.528074 | H17: =IF(H11=1,H14*DnaRatio,0) -> 92.338636 | I17: =IF(I11=1,I14*DnaRatio,0) -> 94.185409 | J17: =IF(J11=1,J14*DnaRatio,0) -> 96.069117 | K17: =IF(K11=1,K14*DnaRatio,0) -> 0 | ... R17: =IF(R11=1,R14*DnaRatio,0) -> 0
A18: CAPEX = 매출 × 과거 3년 CAPEX/매출 | B18: 백만원 | D18: =IF(D11=1,D14*CapexRatio,0) -> 25.804154 | E18: =IF(E11=1,E14*CapexRatio,0) -> 48.138216 | F18: =IF(F11=1,F14*CapexRatio,0) -> 48.485297 | G18: =IF(G11=1,G14*CapexRatio,0) -> 49.144942 | H18: =IF(H11=1,H14*CapexRatio,0) -> 50.127841 | I18: =IF(I11=1,I14*CapexRatio,0) -> 51.130398 | J18: =IF(J11=1,J14*CapexRatio,0) -> 52.153006 | K18: =IF(K11=1,K14*CapexRatio,0) -> 0 | ... R18: =IF(R11=1,R14*CapexRatio,0) -> 0
A19: 순운전자본(기말) | B19: 백만원 | C19: =NWC_Open -> 304.03032 | D19: =IF(D11=1,D13*DSO/DaysYr+D13*COGSR*DIO/DaysYr-D13*COGSR*DPO/DaysYr,C19) -> 143.0809 | E19: =IF(E11=1,E13*DSO/DaysYr+E13*COGSR*DIO/DaysYr-E13*COGSR*DPO/DaysYr,D19) -> 143.19754 | F19: =IF(F11=1,F13*DSO/DaysYr+F13*COGSR*DIO/DaysYr-F13*COGSR*DPO/DaysYr,E19) -> 144.23 | G19: =IF(G11=1,G13*DSO/DaysYr+G13*COGSR*DIO/DaysYr-G13*COGSR*DPO/DaysYr,F19) -> 146.19226 | H19: =IF(H11=1,H13*DSO/DaysYr+H13*COGSR*DIO/DaysYr-H13*COGSR*DPO/DaysYr,G19) -> 149.1161 | I19: =IF(I11=1,I13*DSO/DaysYr+I13*COGSR*DIO/DaysYr-I13*COGSR*DPO/DaysYr,H19) -> 152.09843 | J19: =IF(J11=1,J13*DSO/DaysYr+J13*COGSR*DIO/DaysYr-J13*COGSR*DPO/DaysYr,I19) -> 155.14039 | K19: =IF(K11=1,K13*DSO/DaysYr+K13*COGSR*DIO/DaysYr-K13*COGSR*DPO/DaysYr,J19) -> 155.14039 | ... R19: =IF(R11=1,R13*DSO/DaysYr+R13*COGSR*DIO/DaysYr-R13*COGSR*DPO/DaysYr,Q19) -> 155.14039
A20: ΔNWC(증가 = 유출) | B20: 백만원 | D20: =IF(D11=1,D19-C19,0) -> -160.94941 | E20: =IF(E11=1,E19-D19,0) -> 0.1166315 | F20: =IF(F11=1,F19-E19,0) -> 1.0324679 | G20: =IF(G11=1,G19-F19,0) -> 1.9622561 | H20: =IF(H11=1,H19-G19,0) -> 2.9238452 | I20: =IF(I11=1,I19-H19,0) -> 2.9823221 | J20: =IF(J11=1,J19-I19,0) -> 3.0419685 | K20: =IF(K11=1,K19-J19,0) -> 0 | ... R20: =IF(R11=1,R19-Q19,0) -> 0
A21: 실효세율(누진, 회계연도 과세표준) | B21: % | D21: =IF(D16>0,IF(D16>0,SUMPRODUCT((D16>TaxFrom)*(D16-TaxFrom)*TaxDRate),0)/D16,0) -> 0 | E21: =IF(E16>0,IF(E16>0,SUMPRODUCT((E16>TaxFrom)*(E16-TaxFrom)*TaxDRate),0)/E16,0) -> 0.11 | F21: =IF(F16>0,IF(F16>0,SUMPRODUCT((F16>TaxFrom)*(F16-TaxFrom)*TaxDRate),0)/F16,0) -> 0.11 | G21: =IF(G16>0,IF(G16>0,SUMPRODUCT((G16>TaxFrom)*(G16-TaxFrom)*TaxDRate),0)/G16,0) -> 0.11 | H21: =IF(H16>0,IF(H16>0,SUMPRODUCT((H16>TaxFrom)*(H16-TaxFrom)*TaxDRate),0)/H16,0) -> 0.11 | I21: =IF(I16>0,IF(I16>0,SUMPRODUCT((I16>TaxFrom)*(I16-TaxFrom)*TaxDRate),0)/I16,0) -> 0.11 | J21: =IF(J16>0,IF(J16>0,SUMPRODUCT((J16>TaxFrom)*(J16-TaxFrom)*TaxDRate),0)/J16,0) -> 0.11 | K21: =IF(K16>0,IF(K16>0,SUMPRODUCT((K16>TaxFrom)*(K16-TaxFrom)*TaxDRate),0)/K16,0) -> 0.11 | ... R21: =IF(R16>0,IF(R16>0,SUMPRODUCT((R16>TaxFrom)*(R16-TaxFrom)*TaxDRate),0)/R16,0) -> 0.12370703
A22: 법인세 | B22: 백만원 | D22: =MAX(D15,0)*D21 -> 0 | E22: =MAX(E15,0)*E21 -> 1.4664134 | F22: =MAX(F15,0)*F21 -> 5.1698182 | G22: =MAX(G15,0)*G21 -> 8.9832269 | H22: =MAX(H15,0)*H21 -> 12.980826 | I22: =MAX(I15,0)*I21 -> 17.134736 | J22: =MAX(J15,0)*J21 -> 21.449609 | K22: =MAX(K15,0)*K21 -> 21.878602 | ... R22: =MAX(R15,0)*R21 -> 28.263272
A23: NOPAT | B23: 백만원 | D23: =D15-D22 -> -10.720779 | E23: =E15-E22 -> 11.864617 | F23: =F15-F22 -> 41.828529 | G23: =G15-G22 -> 72.682472 | H23: =H15-H22 -> 105.02668 | I23: =I15-I22 -> 138.63559 | J23: =J15-J22 -> 173.54684 | K23: =K15-K22 -> 177.01778 | ... R23: =R15-R22 -> 200.20615
A24: FCFF(체감 재투자 전) | B24: 백만원 | D24: =D23+D17-D18-D20 -> 171.95735 | E24: =E23+E17-E18-E20 -> 52.283392 | F24: =F23+F17-F18-F20 -> 81.623731 | G24: =G23+G17-G18-G20 -> 112.10335 | H24: =H23+H17-H18-H20 -> 144.31363 | I24: =I23+I17-I18-I20 -> 178.70828 | J24: =J23+J17-J18-J20 -> 214.42098 | K24: =K23+K17-K18-K20 -> 177.01778 | ... R24: =R23+R17-R18-R20 -> 200.20615
A26: FY2026 EBIT(정상) | B26: 백만원 | C26: =D13*Forecast!$C$42 -> -19.98356
A27: FY2026 EBIT(혼합) | B27: 백만원 | C27: =D16 -> -269.99361
A28: 출발 NOPAT(선택 규칙) | B28: 백만원 | C28: =IF(RonicStart="normal",C26-IF(C26>0,SUMPRODUCT((C26>TaxFrom)*(C26-TaxFrom)*TaxDRate),0),C27-IF(C27>0,SUMPRODUCT((C27>TaxFrom)*(C27-TaxFrom)*TaxDRate),0)) -> -19.98356
A29: 명시 마지막 연도 EBIT | B29: 백만원 | C29: =INDEX($D$15:$R$15,MATCH(ExplicitEnd,$D$6:$R$6,0)) -> 194.99645
A30: NOPAT | B30: 백만원 | C30: =C29-IF(C29>0,SUMPRODUCT((C29>TaxFrom)*(C29-TaxFrom)*TaxDRate),0) -> 173.54684
A31: 누적 재투자 | B31: 백만원 | C31: =SUMPRODUCT(($D$5:$R$5>1)*$D$11:$R$11*($D$18:$R$18-$D$17:$R$17+$D$20:$R$20)) -> -239.86863
A32: 증분 ROIC(계산값) | C32: =IF(C31>0,(C30-C28)/C31,0) -> 0
A33: 한계세율(세후 Kd) | C33: =T_Kd -> 0.11
A34: 마지막 연도 매출 | B34: 백만원 | C34: =$R$14 -> 4657.8459
A35: 다음 해 NOPAT | B35: 백만원 | C35: =(C34*(1+GTermCfg)*(Forecast!$C$42+MarginConvAmt))-IF((C34*(1+GTermCfg)*(Forecast!$C$42+MarginConvAmt))>0,SUMPRODUCT(((C34*(1+GTermCfg)*(Forecast!$C$42+MarginConvAmt))>TaxFrom)*((C34*(1+GTermCfg)*(Forecast!$C$42+MarginConvAmt))-TaxFrom)*TaxDRate),0) -> 203.77027
A37: SRP 열 1 | C37: =SRP_1 -> 0
A38: WACC | C38: =(1-WD)*(Rf+BetaL*MRP+SRP_1)+WD*Kd_Pre*(1-C33) -> 0.092121243
A39: RONIC(적용) | C39: =IF(C31<=0,C38,IF(C32<C38,C38,IF(C32>RonicCap,MAX(RonicCap,C38),C32))) -> 0.092121243
A40: FCFF | D40: =D24-IF(D11=1,0,D23*D12/C39) -> 171.95735 | E40: =E24-IF(E11=1,0,E23*E12/C39) -> 52.283392 | F40: =F24-IF(F11=1,0,F23*F12/C39) -> 81.623731 | G40: =G24-IF(G11=1,0,G23*G12/C39) -> 112.10335 | H40: =H24-IF(H11=1,0,H23*H12/C39) -> 144.31363 | I40: =I24-IF(I11=1,0,I23*I12/C39) -> 178.70828 | J40: =J24-IF(J11=1,0,J23*J12/C39) -> 214.42098 | K40: =K24-IF(K11=1,0,K23*K12/C39) -> 138.5863 | L40: =L24-IF(L11=1,0,L23*L12/C39) -> 141.11049 | M40: =M24-IF(M11=1,0,M23*M12/C39) -> 143.58823 | N40: =N24-IF(N11=1,0,N23*N12/C39) -> 146.11552 | O40: =O24-IF(O11=1,0,O23*O12/C39) -> 148.69336 | P40: =P24-IF(P11=1,0,P23*P12/C39) -> 151.32275 | Q40: =Q24-IF(Q11=1,0,Q23*Q12/C39) -> 154.00473 | R40: =R24-IF(R11=1,0,R23*R12/C39) -> 156.74035
A41: 현재가치 | D41: =D40*(1+C38)^(-DCF!D10) -> 168.18002 | E41: =E40*(1+C38)^(-DCF!E10) -> 47.855915 | F41: =F40*(1+C38)^(-DCF!F10) -> 68.401406 | G41: =G40*(1+C38)^(-DCF!G10) -> 86.008999 | H41: =H40*(1+C38)^(-DCF!H10) -> 101.38222 | I41: =I40*(1+C38)^(-DCF!I10) -> 114.95511 | J41: =J40*(1+C38)^(-DCF!J10) -> 126.27797 | K41: =K40*(1+C38)^(-DCF!K10) -> 74.723522 | L41: =L40*(1+C38)^(-DCF!L10) -> 69.666741 | M41: =M40*(1+C38)^(-DCF!M10) -> 64.910382 | N41: =N40*(1+C38)^(-DCF!N10) -> 60.473958 | O41: =O40*(1+C38)^(-DCF!O10) -> 56.343047 | P41: =P40*(1+C38)^(-DCF!P10) -> 52.50276 | Q41: =Q40*(1+C38)^(-DCF!Q10) -> 48.926159 | R41: =R40*(1+C38)^(-DCF!R10) -> 45.589475
A42: 영구가치(가치동인) | B42: 백만원 | C42: =C35*(1-GTermCfg/C39)/(C38-GTermCfg)*IF(MidYear=1,(1+C38)^0.5,1) -> 2311.6201
A43: 영구가치 현재가치 | B43: 백만원 | C43: =C42*(1+C38)^(-DCF!R9) -> 643.29826
...

Sheet Football
A1: Football — 방법별 주당 범위 (원, 가정 하 추정·참고 범위)
A2: 막대 = 낮음~높음, 점 = 대표값, 빨간 점선 = 기준일 종가. 투자 권유 아님. 시세 자료 출처: 한국거래소 통계정보
A4: 그룹 | B4: 항목 | C4: 낮음 | D4: 높음 | E4: 대표 | F4: y | G4: y | H4: 정의
A5: DCF(연결) | B5: DCF 비관 | C5: =MIN(Scenarios!$B$6:$D$6) -> 8690.3282 | D5: =MAX(Scenarios!$B$6:$D$6) -> 8702.4406 | E5: =Scenarios!$B$6 -> 8702.4406 | F5: =ROWS(B5:$B$13) -> 9 | G5: =F5 -> 9 | H5: SRP 2%~0% 범위, 대표 = SRP 0%
